Workbook

Sheet 1. Instructions
A1: NRM1 COST ESTIMATE TOOL — v5.19 (October 2026)
A2: Prices and scope of works for Projento, in four sheets. Prepared by Nabil Kayali.
A4: THE FOUR SHEETS
A5: 2. Rates | B5: Every price. One row per item or option, the rates side by side. The sheet you maintain.
A6: 3. Settings | B6: Project types (and which rate column each reads), building uses, specification and intervention levels, location factors, benchmarks, quantity ratios, factors and percentages.
A7: 4. Scope rules | B7: How the app uses each item: when it shows, what starts ticked, how the quantity is estimated, BCIS split and old codes. Rarely needs changing.
A8: 1. Instructions | B8: This page: how to read and change the workbook, the self-checks and the update log.
A10: READING '2. RATES'
A11: Rates | B11: Mid-point UK rates before the location factor, preliminaries and overheads & profit — the app adds those from '3. Settings'.
A12: Which column | B12: Refurbishment, Fit-out and Demolition only read the Refurb & Fit-out columns (the same price for both). New build, Extension and External works only read the New build & Extension columns. Other or mixed reads Refurb & Fit-out, then New build where that is 0.
A13: Blank Basic or High | B13: Same as Standard.
A14: Dash (–) = no price | B14: No price for that project type, so the item (or option) cannot be selected in Q2.3 Scope of works for it. The cell holds 0.
A15: Building use | B15: ALL = any building use. A code (e.g. HOS, HEA, RES STU) = a rate for that use only; the app uses it for that use and the ALL row otherwise.
A16: What's included / Not included | B16: What the rate covers, and what is priced elsewhere (with the code of the row that prices it) or not at all. Size bands (Small / Medium / Large) say what each lump sum assumes.
A17: Units | B17: m² GIFA = gross internal floor area of the building worked on (Q1.5). m² footprint = ground-floor area (GIFA ÷ storeys). m² upper floors = GIFA − footprint. m² roof = roof on plan (= footprint). m² external = the external works area. nr … = a count (WCs, lifts, spaces). band = one lump sum.
A18: Formula cells | B18: A few options are priced as a multiple of another row (e.g. air source heat pump = gas boiler × 1.3). The Source column shows the row and factor; change the factor in the cell formula.
A19: Code and Rate key | B19: Code (0.1, 4.2a) is for reading. Rate key (last column, grey) is permanent: saved projects store it. Never change or reuse a Rate key.
A20: Spon's check | B20: Spon's Architects' & Builders' Price Book 2024 figure converted to this workbook's basis (Q3 2026, UK mid-point, excluding prelims and OH&P), with the PDF page.
A21: Tender check | B21: Lakeside Staff & Family Flats tender returns (29 Sept 2026) converted to this workbook's basis: the median of the four credible bids (BSN, Chiel, Harrabin, William Gough with its kitchen error corrected; Watkin Jones excluded at twice the field) ÷ 0.94 West Midlands factor, per this row's unit, on 3,306 m² measured floor area (49 flats, the Warden's house and nine stair cores). Excludes the contractors' preliminaries and OH&P. Lines starting 'CS:' are the Computer Science Building decarbonisation tender returns (Harrabin and Chiel, March 2024; two bids, so the mean): tender × 1.07 (to Q3 2026) ÷ 0.94, on 3,495 m² GIA (UoW Estates CAD outlines) and 699 m² of roof. Evidence only: no rate was changed for them in v5.8. Final out-turn (financial statement, July 2026): construction £2.73m, +3.4% on a £2.64m contract; total project £3.13m excl. VAT. WF lines: Whitefields demolition (17 blocks, UoW main campus), the Total Reclaims contract (tendered Feb 2026, Option 2) — the figure is also in column R, Whitefields rate. CC lines: the Claycroft student residences refurbishment (679 beds, three occupied blocks, UoW main campus), Morgan Sindall G4 contract (May 2025, SCAPE) — the figure is also in column S, Claycroft rate.
A22: Whitefields rate | B22: Column R on '2. Rates': the Whitefields demolition contract figure for that row (Total Reclaims, £525,676; AFC £532,445 at FS 16, Jul 2026), in the row's unit and on this workbook's basis — line items without the contractor's prelims and OH&P, ÷ 0.94 West Midlands factor, × 1.014 to Q3 2026. Quantities from the owner: 17 blocks, 3,740 m² GIA (about 220 m² each over ground and first floors), 2,210 m² footprint (about 130 m² each), 8,000 m² site. Evidence only: the app does not read this column and no rate changed.
... A24: Project rate columns (T–Z) | B24: Columns T–Y on '2. Rates' hold the other real projects' figures in the row's unit and on this workbook's basis, beside Whitefields (R) and Claycroft (S): T Lakeside S&F (tender Sep 2026, median of 4 bids); U Computer Science decarbonisation (tender Mar 2024, mean of 2 bids); V Scarman Public Toilets Phase 2 (HIGH spec, tender Apr 2026, median of 6 bids; per m² over the 71 m² toilet area); W Co-op grocery store fit-out (Kingfisher contract Aug 2025, 885 m²); X IBRB café servery (Senevo winning bid 2025, 72 m² café, 28 m² servery); Y Riley Court Psychology full refurbishment (Maris signed contract £9.15m, GMP Nov 2024, GIFA 3,850 m²). Each excludes the contractor's prelims, OH&P and design, rebased to Q3 2026 and ÷ 0.94 West Midlands. Column Z is the average of R–Y for the row. Projects differ in scope and specification, so expect spread. Not on '2. Rates': scaffold for envelope works £42 (CS) and £33 (Claycroft) per m² GIFA; retail refrigeration £379 and retailer equipment £373 per m² (Co-op); preliminaries Lakeside ~9%, Whitefields 16.8%, Claycroft 11.3%, Scarman 14%, Co-op 7.2%, IBRB 17.7%, Riley Court 5.5% (+4% contractor PM and design). Evidence only: the app does not read these columns and no rate changed. Column AA is Claude's suggested Refurb & Fit-out Standard rate for each row with evidence, and AB the reason (Raise / Lower / Keep). They are suggestions for the owner only: the app does not read them, and a rate changes only when the owner edits the rate columns.
A25: PRICE SOURCE (column 'Source' on '2. Rates')
A26: Your figure | B26: Set by the owner.
A27: Spon's-based (approved) | B27: Suggested from Spon's 2024 and approved by the owner.
A28: Kept after Spon's check | B28: Compared with Spon's 2024; the owner kept the existing rate.
A29: Older workbook (v4.5) | B29: Carried from v4.5, not yet checked.
A30: Unverified † | B30: Estimated, not yet checked. Lines using it are marked † on reports until the source changes.
A31: Tender – Lakeside S&F (Sep 2026) | B31: From the Lakeside Staff & Family Flats tender returns (29 Sept 2026); the figure and bid range are in the 'Tender check' column.
A33: HOW TO CHANGE THINGS
A34: Change a price | B34: Edit the cell on '2. Rates' and update its Source. Save in Excel.
A35: Add an option | B35: Insert a row on '2. Rates' under the item with the next Rate key (e.g. S-0039-16), and a row for that key on '4. Scope rules' ▶ options.
A36: Add an item | B36: Insert its rows on '2. Rates', a row on ▶ items (next unused Scope ID — never reuse one) and a row per option on ▶ options.
A37: When an item shows, or its quantity | B37: 4. Scope rules'.
A38: A percentage, ratio or factor | B38: 3. Settings'.
A39: After any change | B39: Check the self-checks below all read 0, bump the Version on '3. Settings', add a line to the update log, save in Excel.
A40: Needs a code change | B40: A new column, pricing type, input name or 'When selected' effect type; renamed sheets, ▶ markers or column headers.
A42: SCOPE RULES SHEET — WHAT THE COLUMNS MEAN
A43: Project type codes | B43: NB New build · EX Extension · RF Refurbishment · FO Fit-out · EW External works only · DM Demolition only · OM Other or mixed. Several codes separated by spaces, e.g. "NB EX RF". "—" means none.
A44: Building use codes | B44: RES Residential · STU Student · OFF Commercial offices · EDU Education · HEA Healthcare · RET Retail · IND Industrial / warehouse · HOS Hospitality / leisure · MIX Mixed use · OTH Other · ALL any building use.
A45: Shown on / Pre-ticked on | B45: The project types an item is offered on, and the ones where "Use typical scope" ticks it.
...

Sheet 2. Rates
A1: RATES — mid-point UK rates, before the location factor, preliminaries and OH&P
A2: Two price families: Refurb & Fit-out (Refurbishment, Fit-out, Demolition only) and New build & Extension (New build, Extension, External works only). A blank Basic or High = same as Standard. A dash (–) = no price, so the item cannot be selected in Q2.3 for that project type.
A3: Units: m² GIFA = gross internal floor area; m² footprint = ground-floor area. When an item shows and how its quantity is estimated are on '4. Scope rules'. Rate key (grey, last column) is permanent — never change it.
A5: Code | B5: Item | C5: Option | D5: Building use | E5: What's included | F5: Not included (priced elsewhere, or not at all) | G5: Unit | H5: Refurb & Fit-out Basic | I5: Refurb & Fit-out Std | J5: Refurb & Fit-out High | K5: New build & Extension Std | L5: New build & Extension High | M5: Source | N5: Spon's check (converted, PDF page) | O5: Rate key | P5: NK Comment | Q5: Tender check (this row's unit, on this workbook's basis. Unlabelled = Lakeside S&F, Sep 2026: median of 4 bids ÷ 0.94. CS = Computer Science decarbonisation, Mar 2024: 2 bids × 1.07 ÷ 0.94. WF = Whitefields demolition, Total Reclaims contract 2026: line items × 1.014 ÷ 0.94 — the figure is also in column R. CC = Claycroft refurbishment, Morgan Sindall G4 contract May 2025: packages × 1.034 ÷ 0.94 — the figure is also in column S) | R5: Whitefields rate (£ per this row's unit, this workbook's basis: Total Reclaims contract 2026, excl. the contractor's prelims and OH&P, ÷ 0.94 × 1.014. Evidence only — the app does not read it) | S5: Claycroft rate (£ per this row's unit, this workbook's basis: Morgan Sindall G4 contract, May 2025 — sub-contract packages excl. Morgan Sindall's prelims, risk, fee and design, × 1.034 ÷ 0.94, on 17,172 m² GIA measured. 2.10 fire stopping is the forecast out-turn (Mace Val 16, Sep 2026). Evidence only — the app does not read it) | T5: Lakeside rate (£ per this row's unit, this workbook's basis: Lakeside Staff & Family Flats refurbishment, tender Sep 2026, median of 4 bids ÷ 0.94. Evidence only — the app does not read it) | U5: Computer Science rate (£ per this row's unit, this workbook's basis: CS Building decarbonisation, tender Mar 2024, mean of 2 bids × 1.07 ÷ 0.94; roof per m² footprint; 5.1b is the whole M&E package. Evidence only) | V5: Scarman rate (£ per this row's unit, this workbook's basis: Scarman Public Toilets Phase 2, HIGH specification, tender Apr 2026, median of 6 bids × 1.007 ÷ 0.94; per m² figures over the 71 m² toilet area only. Evidence only) | W5: Co-op rate (£ per this row's unit, this workbook's basis: Co-op grocery store fit-out, Kingfisher CSA, contract Aug 2025 × 1.03 ÷ 0.94, over 885 m². Evidence only) | X5: IBRB café rate (£ per this row's unit, this workbook's basis: IBRB café servery fit-out, Senevo winning bid 2025 × 1.035 ÷ 0.94, over 72 m² (catering kitchen per 28 m² servery). Evidence only) | Y5: Riley Court rate (£ per this row's unit, this workbook's basis: Psychology building full refurbishment, Maris signed contract CSA £9.15m, GMP Nov 2024 × 1.05 ÷ 0.94, GIFA 3,850 m². Evidence only) | Z5: Average of project rates (mean of columns R–Y that hold a figure for this row. Projects differ in scope and specification, so read it with the column notes. Evidence only — the app does not read it) | AA5: Suggested Refurb & Fit-out Std rate (Claude's suggestion from the project columns R–Y, 4 Oct 2026, for the owner to accept, change or ignore. Evidence only — the app does not read it) | AB5: Reason for the suggestion
A6: GROUP 0 — FACILITATING WORKS
A7: 0.1 | B7: Asbestos removal | D7: ALL | E7: Survey-led removal and disposal of asbestos and other hazardous materials from the building worked on (on New build: the building being demolished), incl. enclosures, air testing and licensed disposal | F7: The asbestos refurbishment & demolition survey itself (a fee) | G7: m² GIFA | I7: 25 | K7: 25 | M7: Your figure | N7: £13 (p.248) | O7: S-0001-01 | Q7: WF: £8.1 on the contract (Total Reclaims, £28,050 to the asbestos BoQ) over 3,740 m² GIA (17 blocks × about 220 m², owner's figures). Five bids on the same BoQ: £8.1–£42.5, median £12.7. Mace's pre-tender allowance was £85,000 (£24.5). The R&D survey (£9,400) was a fee. | R7: 8.1 | Z7: =AVERAGE(R7:Y7) -> 8.1 | AA7: 25 | AB7: Keep. Matches Mace pre-tender allowance (£24.5); one low tender (£8) is not enough to cut it.
A8: 0.2 | B8: Demolition of existing building | D8: ALL | E8: Demolition of the whole existing building to ground level: soft strip, disconnection of services, breaking out ground slab and shallow foundations, removal and disposal of arisings | F8: Asbestos removal (0.1); basements and deep foundations; contaminated ground (0.4) | G8: m² demolished | I8: 100 | K8: 100 | M8: Your figure | N8: £131–£397 (p.413) | O8: S-0002-01 | Q8: WF: £73 per m² demolished on the contract, 3,740 m² GIA (17 blocks × about 220 m², owner's figures): soft strip, demolish, slabs and foundations £34; disconnecting and cutting back drainage, water, gas, electrical and telecoms, plus Trinity / Honeywell fire alarm, security and metering removal, £39. Core demolition across five bids £34–£70 (median £46). About £15k per block. Excludes the water-main replacement (0.7) and the contractor's own £15k provisional sums for the Trinity / Honeywell work, which those quotes replace. | R8: 73.3 | Z8: =AVERAGE(R8:Y8) -> 73.3 | AA8: 100 | AB8: Lower. Whitefields £73 on simple 2-storey masonry; £100 leaves room for framed or taller buildings.
A9: 0.3 | B9: Strip-out | D9: ALL | E9: Removal of existing finishes, ceilings, non-structural partitions, fittings and redundant services back to shell, incl. disposal | F9: Structural alterations (7.2); asbestos (0.1) | G9: m² GIFA | I9: 55 | K9: 0 | M9: Tender – Lakeside S&F (Sep 2026) | N9: £35–£99 (p.242, 246) | O9: S-0003-01 | Q9: £54 (bids £36–£56) for a partial strip-out: finishes, fittings, redundant electrics and protection CC: £51.4 on the Claycroft G4 contract (Cawarden, £801,990): full strip-out of three occupied student blocks, 17,172 m² GIA. Three bids £802k–£928k. | S9: 51.4 | T9: 54 | V9: 217 | W9: 48.8 | X9: 11.5 | Y9: 54.9 | Z9: =AVERAGE(R9:Y9) -> 72.933333 | AA9: 55 | AB9: Keep. Lakeside, Claycroft, Co-op and Riley Court all £49–55. Scarman and IBRB are tiny jobs.
A10: 0.4 | B10: Contaminated land | D10: ALL | E10: Treatment or removal and disposal of contaminated ground under the building (on External works only: the site area), incl. capping layer and verification | F10: Site investigation (a fee). Not offered on refurbishment, fit-out or demolition only | G10: m² GIFA | I10: 0 | K10: 60 | M10: Your figure | N10: £47–£164 (p.112) | O10: S-0004-01
A11: 0.5 | B11: Ground improvement | D11: ALL | E11: Ground stabilisation under the building footprint: mine-working grouting, vibro-compaction or soil improvement | F11: Piling (in 1.1b Foundations) | G11: m² footprint | I11: 0 | K11: 35 | M11: Your figure | O11: S-0005-01
A12: 0.6 | B12: Tree removal | D12: ALL | E12: Per tree: felling, stump grinding or removal, and disposal | F12: Replacement planting (8.10); tree surveys and protection orders | G12: nr trees | I12: 750 | K12: 750 | M12: Your figure | N12: £340–£833 (p.452) | O12: S-0006-01
A13: 0.7 | B13: Service diversions | D13: ALL | E13: Diverting or protecting existing underground services (drains, cables, pipes) that cross the building footprint, incl. utility company charges for the diversion | F13: New connections for the building (8.4 External utilities) | G13: m² footprint | I13: 100 | K13: 100 | M13: Your figure | O13: S-0007-01 | Q13: WF: £36 per m² footprint on the contract (17 × about 130 m² = 2,210 m² footprint): replacing 254 m of ductile iron water main across the site in MDPE, with temporary water, trenching, stone surround and tarmac reinstatement (£74k; about £315/m of main). £44 with the changes pending at FS 16, Jul 2026 (trial pits on the district heating and water mains, out-of-hours water works: £16.7k). | R13: 36.3 | Z13: =AVERAGE(R13:Y13) -> 36.3 | AA13: 100 | AB13: Keep. One water-main job (£36); diversions are too site-specific to move the rate.
A14: GROUP 1 — SUBSTRUCTURE
A15: 1.1a | B15: Foundations | C15: Standard | D15: ALL | E15: Excavation, disposal, concrete strip or pad foundations and ground beams up to ground-floor slab level | F15: Ground floor slab (1.2); basement (1.3); ground improvement (0.5) | G15: m² footprint | I15: 0 | K15: 115 | L15: 140 | M15: Spon's-based (approved) | N15: £114–£158 (p.292) | O15: S-0008-01
A16: 1.1d | B16: Foundations | C16: Standard | D16: IND | E16: Industrial / warehouse: pad foundations to the portal-frame columns, column casings below slab and a perimeter ground beam under the cladding | F16: Ground floor slab (1.2); basement (1.3); ground improvement (0.5) | G16: m² footprint | I16: 0 | K16: 22 | L16: 30 | M16: Spon's-based (approved) | N16: Shed model: pads, casings, perimeter beam and dock foundations £8.80 per m² GIFA at 29,640 m²; about £13.60 at 4,000 m² (more perimeter per m²) × 1.30 = £18 (p.221) | O16: S-0008-04
A17: 1.1b | B17: Foundations | C17: Piled | D17: ALL | E17: Piled foundations (CFA or mini-piles) with pile caps and ground beams, for poor ground | F17: Ground floor slab (1.2); basement (1.3); ground improvement (0.5) | G17: m² footprint | I17: 0 | K17: 260 | L17: 320 | M17: Spon's-based (approved) | N17: £250–£335 (p.292) | O17: S-0008-02
A18: 1.1c | B18: Foundations | C18: Not sure | D18: ALL | E18: Priced as standard foundations and adds a piling risk to the report until ground conditions are known | F18: Ground floor slab (1.2); basement (1.3); ground improvement (0.5) | G18: m² footprint | I18: =I15*1 -> 0 | K18: =K15*1 -> 115 | L18: =L15*1 -> 140 | M18: Older workbook (v4.5) (= 1.1a × 1) | O18: S-0008-03
A19: 1.1e | B19: Foundations | C19: Not sure | D19: IND | E19: Industrial / warehouse: foundation type not yet known — priced as standard pad foundations (1.1d) and raises a piling risk | F19: Ground floor slab (1.2); basement (1.3); ground improvement (0.5) | G19: m² footprint | I19: =I16*1 -> 0 | K19: =K16*1 -> 22 | L19: =L16*1 -> 30 | M19: Spon's-based (approved) (= 1.1d × 1) | O19: S-0008-05
A20: 1.2a | B20: Ground floor slab | D20: ALL | E20: Excavation to formation, hardcore sub-base, blinding, DPM, insulation and reinforced concrete ground-bearing slab | F20: Floor finishes and screed (3.2) | G20: m² footprint | I20: 0 | K20: 160 | L20: 195 | M20: Spon's-based (approved) | N20: £131–£196 (p.299, 300, 301) | O20: S-0009-01
A21: 1.2b | B21: Ground floor slab | D21: IND | E21: Industrial / warehouse: 200 mm reinforced ground-bearing slab to FM2 flatness with surface hardener and sealed joints, type 1 sub-base, fill to make up levels and a floor survey | F21: Floor finishes and screed (3.2) | G21: m² footprint | I21: 0 | K21: 100 | L21: 125 | M21: Spon's-based (approved) | N21: Shed model: slab £61 + fill £8.75 + type 1 £8.10 + survey £0.60 = £78.50 per m² × 1.30 = £102 (p.221) | O21: S-0009-02
A22: 1.3 | B22: Basement | D22: ALL | E22: Bulk excavation and disposal, temporary works, reinforced concrete basement walls and floor, and waterproofing (tanking) | F22: Finishes and services inside the basement | G22: m² basement | I22: 0 | K22: 600 | L22: 1000 | M22: Your figure | N22: £438–£533 (p.302) | O22: S-0010-01
A23: GROUP 2 — SUPERSTRUCTURE AND ENVELOPE
A24: 2.1a | B24: Frame | D24: ALL | E24: New build: steel or concrete frame (columns, beams, bracing) incl. fire protection. Refurbishment: strengthening or adapting the existing frame | F24: Floor slabs (1.2, 2.2); roof structure (2.5) | G24: m² GIFA | H24: - | I24: - | J24: - | K24: 350 | L24: 550 | M24: Kept after Spon's check | N24: Refurb £118 (p.242) · New build £103–£201 (p.265, 302) | O24: S-0011-01
A25: 2.1b | B25: Frame | D25: IND | E25: Industrial / warehouse: steel portal frame with cold-rolled roof purlins and wall rails, painted, incl. the frame of an office block inside the shed | F25: Floor slabs (1.2, 2.2); roof structure (2.5) | G25: m² GIFA | H25: - | I25: - | J25: - | K25: 90 | L25: 120 | M25: Spon's-based (approved) | N25: Shed model: portal frame £70.60 per m² GIFA × 1.30 = £92 (p.221) | O25: S-0011-02
A26: 2.2 | B26: Upper floors | D26: ALL | E26: Upper floor slabs or decks (composite steel deck, precast or timber) incl. balconies. Refurbishment: repairing or strengthening existing floors | F26: Floor finishes (3.2); frame (2.1) | G26: m² upper floors | H26: - | I26: - | J26: - | K26: 110 | L26: 135 | M26: Spon's-based (approved) | N26: Refurb £25 (p.242) · New build £93–£136 (p.308) | O26: S-0012-01
A27: 2.3 | B27: Stairs and ramps | D27: ALL | E27: Staircases and ramps with finishes, handrails and balustrades | F27: Lifts (5.16) | G27: m² GIFA | H27: - | I27: - | J27: - | K27: 20 | L27: 35 | M27: Spon's-based (approved) | N27: Refurb £43 (p.242) · New build £6–£35 (p.266, 260) | O27: S-0013-01
A28: 2.4 | B28: Mezzanine floor | D28: ALL | E28: Free-standing steel mezzanine floor with deck, access stair, balustrade and fire protection | F28: Finishes and services on the mezzanine | G28: m² mezzanine | H28: 180 | I28: 250 | J28: 350 | K28: 250 | L28: 350 | M28: Kept after Spon's check | N28: £187–£234 (p.302) | O28: S-0014-01
A29: 2.5a | B29: Roof | C29: Full roof | D29: ALL | E29: Roof structure, covering, insulation, rainwater goods, roof access and edge protection (measured on plan, = footprint). Refurbishment: re-covering and insulating the existing roof | F29: Rooflights over standard provision; green roof (8.11); solar PV (5.17) | G29: m² roof | H29: 155 | I29: 190 | J29: 345 | K29: 220 | L29: 300 | M29: Your figure | N29: Refurb £94–£220 (p.246, 313) · New build £181–£258 (p.310, 313) | O29: S-0015-01 | Q29: Loft insulation only: £32 — see 2.5b. CS: £313 (bids £288–£338) per m² of roof re-covered (699 m², less than the footprint) for a flat warm-roof overlay on the kept asphalt: AVCL, 120 mm PIR, two-layer felt, insulated upstands, new copings, ballast relaid. Scaffold extra (see 2.7). Claycroft pitched re-roof £627–£704. CC: £517 per m² of roof plan (5,747 m² footprint) on the G4 contract: strip concrete tiles, top-hat spacers, Euroclad secret-fix metal over-roof, hips and verges, new eaves, gutters and soffits (£596 per m of eaves), incl. Metclad's design and prelims; excl. the bay-window cladding and scaffold (scaffold £99 per m² of plan). Forecast out-turn with roof timber remedials £601. Tiled like-for-like alternative about £460 (Stage 3). | S29: 516.9 | U29: 182 | Z29: =AVERAGE(R29:Y29) -> 349.45 | AA29: 190 | AB29: Raise. Computer Science £182 per m² footprint. Claycroft metal over-roof £517 is a High case.
A30: 2.5c | B30: Roof | C30: Full roof | D30: IND | E30: Industrial / warehouse: insulated trapezoidal composite roof panels with rooflights (about 15%), valley and eaves gutters, syphonic rainwater drainage, roof access and fall-arrest system (measured on plan, = footprint) | F30: Rooflights over standard provision; green roof (8.11); solar PV (5.17) | G30: m² roof | H30: 155 | I30: 190 | J30: 345 | K30: 115 | L30: 150 | M30: Spon's-based (approved) | N30: Shed model: roof £90.24 per m² × 1.30 = £117 (p.222) | O30: S-0015-03
A31: 2.5b | B31: Roof | C31: Loft insulation only | D31: ALL | E31: Loft insulation top-up only, roof kept: remove and dispose of old quilt, lay 300 mm mineral wool quilt at ceiling level between and over joists (measured on plan, = footprint) | F31: Roof covering, structure and repairs (2.5a); fire barriers in the roof void (2.10). Not offered on new build | G31: m² roof | I31: 32 | K31: 0 | M31: Tender – Lakeside S&F (Sep 2026) | O31: S-0015-02 | Q31: £32 (bids £29–£39) on 1,099 m², incl. removing the old insulation | T31: 32 | Z31: =AVERAGE(R31:Y31) -> 32 | AA31: 32 | AB31: Keep. Lakeside tender.
A32: 2.6a | B32: External walls | D32: ALL | E32: External walls and facade: masonry, cladding or curtain wall (solid parts), insulation and internal lining. Refurbishment: repairs, re-rendering or over-cladding | F32: Windows and external doors (2.7) | G32: m² GIFA | H32: 50 | I32: 100 | J32: 183 | K32: 220 | L32: 340 | M32: Your figure | N32: Refurb £18–£61 (p.242, 246) · New build £75–£338 (p.266, 324) | O32: S-0016-01 | Q32: CS: £48 (bids £45–£51) for insulated render to part of the façade of an occupied 4-storey building. With the brick remedials under it (see 7.1a): £97 (bids £70–£122). Scaffold extra (see 2.7). | U32: 48 | Y32: 170.5 | Z32: =AVERAGE(R32:Y32) -> 109.25 | AA32: 100 | AB32: Raise. CS part render £48; Riley Court full envelope upgrade £171 (cladding, insulated linings).
A33: 2.6b | B33: External walls | D33: IND | E33: Industrial / warehouse: insulated composite wall cladding (micro-rib and trapezoidal panels), parapet cladding, flashings and access equipment. Priced for a unit of about 2,000–5,000 m² with 8–10 m eaves; smaller units have more wall per m² GIFA | F33: Windows and external doors (2.7) | G33: m² GIFA | H33: 50 | I33: 100 | J33: 183 | K33: 100 | L33: 140 | M33: Spon's-based (approved) | N33: Shed model: cladding about £115 per m² of wall × 1.30 = £150; a 4,000 m² unit has about 0.67 m² of wall per m² GIFA = £100 (p.222) | O33: S-0016-02
A34: 2.7a | B34: Windows and external doors | D34: ALL | E34: Windows, external doors, entrance screens and glazing, with ironmongery | F34: Curtain walling solid panels (2.6) | G34: m² GIFA | H34: 105 | I34: 140 | J34: 210 | K34: 210 | L34: 303 | M34: Your figure | N34: Refurb £107 (p.246) · New build £122–£226 (p.266, 333) | O34: S-0017-01 | Q34: CS: £210 (bids £192–£228) for triple-glazed windows, curtain walling and doors on a whole 4-storey building (openings ≈ 16% of GIFA, ≈ £1,330/m² of opening), incl. take-out, closers, fire barriers, reveals, boards and decs (≈ 30% on top of supply and fit). 17% above High. The low bid left out the curtain walling. Scaffold for envelope works (in the bids' prelims): £42 (bids £35–£49) per m² GIFA, extra to 2.5a, 2.6 and 2.7. Out-turn: window design development added £86k (3.3% of the contract sum) after award. | U34: 210 | W34: 24.4 | Y34: 146.7 | Z34: =AVERAGE(R34:Y34) -> 127.03333 | AA34: 140 | AB34: Raise. Riley Court new windows £147; CS triple glazing £210 (High). Co-op was refinish only.
A35: 2.7b | B35: Windows and external doors | D35: IND | E35: Industrial / warehouse: office windows, curtain walling and entrance doors, personnel escape doors and plant-room louvres. Loading and dock doors are in 4.13 Warehouse | F35: Curtain walling solid panels (2.6) | G35: m² GIFA | H35: 105 | I35: 140 | J35: 210 | K35: 25 | L35: 40 | M35: Spon's-based (approved) | N35: Shed model: office glazing £119 per m² of office (about £14 per m² GIFA at 10% offices) + escape doors and louvres £3.60 = £17.50 × 1.30 = £23 (p.222) | O35: S-0017-02
A36: 2.8 | B36: Internal walls | D36: ALL | E36: Internal walls and partitions (stud or block), incl. acoustic and fire-rated partitions, and toilet IPS panels | F36: Wall finishes (3.1); doors (2.9) | G36: m² GIFA | H36: 68 | I36: 150 | J36: 218 | K36: 150 | L36: 218 | M36: Your figure | N36: £115–£167 (p.275, 243) | O36: S-0018-01 | W36: 26.4 | Y36: 246.9 | Z36: =AVERAGE(R36:Y36) -> 136.65 | AA36: 150 | AB36: Raise. Riley Court £247 (acoustic academic partitions); Co-op £26 was a light shop fit-out.
A37: 2.9 | B37: Internal doors | D37: ALL | E37: Internal doorsets (frame, leaf, ironmongery, decoration), incl. fire doors | F37: External doors (2.7) | G37: m² GIFA | H37: 50 | I37: 100 | J37: 200 | K37: 100 | L37: 200 | M37: Your figure | N37: Refurb £62–£147 (p.247, 255) · New build £38–£163 (p.275, 251) | O37: S-0019-01 | V37: 99 | W37: 9.1 | Y37: 163.7 | Z37: =AVERAGE(R37:Y37) -> 90.6 | AA37: 100 | AB37: Raise. Riley Court £164, Scarman £99; Co-op £9 reused most doors.
A38: 2.10 | B38: Fire stopping | D38: ALL | E38: Upgrading fire stopping and compartmentation in an existing building: sealing service penetrations, fire barriers in voids and cavities | F38: Fire doors (2.9); fire alarm (5.11) | G38: m² GIFA | H38: 15 | I38: 30 | J38: 60 | K38: 15 | L38: 30 | M38: Kept after Spon's check | O38: S-0020-01 | Q38: £13.5 (bids £7–£32) for local fire stopping only — in line with Basic £15 CC: £96 forecast out-turn (Mace Val 16, Sep 2026; £88 if the Claycroft 2 CE replaces its provisional sum), against £22 for the £350k provisional sum in the G4 contract. By block: Claycroft 1 £53 (final); Claycroft 3 £76 (measured: about 18 seals per bed at about £42 each; access 22% of the cost); Claycroft 2 £135–£155 (under review). Excludes £1.30m of compartment-wall head remediation on Claycroft 3, which included a 16-week delay. | S38: 95.8 | T38: 13.5 | V38: 24 | W38: 3.4 | Y38: 15.6 | Z38: =AVERAGE(R38:Y38) -> 30.46 | AA38: 30 | AB38: Keep. Most projects £3–24; Claycroft £96 out-turn (surveyed occupied residential) is a High case.
A39: GROUP 3 — INTERNAL FINISHES
A40: 3.1 | B40: Wall finishes | D40: ALL | E40: Plaster or dry lining, decoration and wall tiling, incl. tanking in wet areas | F40: Wall panelling as joinery (4.5) | G40: m² GIFA | H40: 30 | I40: 75 | J40: 140 | K40: 55 | L40: 140 | M40: Your figure | N40: Refurb £89–£119 (p.247, 255) · New build £56–£134 (p.251, 267) | O40: S-0021-01 | Q40: £72 (bids £60–£84) incl. bathroom wall cladding, kitchen tiling and full redecoration — confirms £75 CC: £99 on the G4 contract: decoration (RE Martin, £1.02m; three bids £1.02m–£1.16m), making good (£274k) and PVC hygienic wall cladding (£251k). Includes painting ceilings and doors. | S40: 99.3 | T40: 72 | V40: 304 | W40: 26.6 | X40: 49 | Y40: 39.4 | Z40: =AVERAGE(R40:Y40) -> 98.383333 | AA40: 75 | AB40: Keep. Lakeside £72, Claycroft £99, Riley Court £39 (decoration only). Scarman is toilet-area only.
A41: 3.2a | B41: Floor finishes | C41: Raised access floor: No | D41: ALL | E41: Screed and floor coverings (carpet, vinyl, tiles, timber), skirtings and entrance matting, incl. tanking in wet areas | F41: Structural slabs (1.2, 2.2) | G41: m² GIFA | H41: 51 | I41: 85 | J41: 227 | K41: 85 | L41: 227 | M41: Your figure | N41: Refurb £72–£215 (p.247, 256) · New build £75–£110 (p.251, 261) | O41: S-0022-01 | Q41: Residential: £51 — see 3.2c | V41: 177 | W41: 21.5 | Y41: 95.3 | Z41: =AVERAGE(R41:Y41) -> 97.933333 | AA41: 85 | AB41: Raise slightly. Riley Court £95 full replacement; Co-op £22 kept its floor. Scarman is toilet-area only.
...

Sheet 3. Settings
A1: SETTINGS — every other number the app reads
A2: Each table starts at its ▶ marker and ends at the first blank row. To add a row, insert it inside the table (above the blank row). Don't rename markers or headers: the app finds tables by them.
A4: ▶ workbook_info | B4: Version stamped on every report the app produces. Update on every change
A5: Field | B5: Value | C5: Notes
A6: Version | B6: 5.27 | C6: Bump on every published change (5.3, 5.4 …) and add a line to the update log
A7: Date | B7: 46307
A8: Owner | B8: Nabil Kayali
A10: ▶ building_uses | B10: Q1.3 options. The Code is what '2. Rates' and '4. Scope rules' uses
A11: Code | B11: Building use (label on screen) | C11: Treated as residential | D11: Notes
A12: RES | B12: Residential | C12: Yes
A13: STU | B13: Student accommodation (PBSA / halls) | C13: Yes
A14: OFF | B14: Commercial offices | C14: No
A15: EDU | B15: Education | C15: No
A16: HEA | B16: Healthcare | C16: No
A17: RET | B17: Retail | C17: No
A18: IND | B18: Industrial / warehouse | C18: No
A19: HOS | B19: Hospitality / leisure | C19: No
A20: MIX | B20: Mixed use | C20: No | D20: Every item listed; nothing hidden under More items
A21: OTH | B21: Other | C21: No | D21: Every item listed; nothing hidden under More items
A22: ALL | B22: (any building use) | D22: Used on '2. Rates' and '4. Scope rules' only: the item or rate applies to every building use
A24: ▶ project_types | B24: Q1.2 options. The rate column read for each specification level. The Code is what '2. Rates' and '4. Scope rules' uses
A25: Code | B25: Project type (label on screen) | C25: Basic column | D25: Standard column | E25: High column | F25: Uses level of intervention | G25: Notes
A26: NB | B26: New Build | C26: New build & Extension Std | D26: New build & Extension Std | E26: New build & Extension High | F26: No | G26: There is no Basic new-build rate, so Basic reads Standard
A27: EX | B27: Extension | C27: New build & Extension Std | D27: New build & Extension Std | E27: New build & Extension High | F27: No | G27: Same rates as New build (owner, 27 Sept 2026)
A28: RF | B28: Refurbishment | C28: Refurb & Fit-out Basic | D28: Refurb & Fit-out Std | E28: Refurb & Fit-out High | F28: Yes
A29: FO | B29: Fit-out | C29: Refurb & Fit-out Basic | D29: Refurb & Fit-out Std | E29: Refurb & Fit-out High | F29: Yes | G29: Same rates as Refurbishment
A30: EW | B30: External works only | C30: New build & Extension Std | D30: New build & Extension Std | E30: New build & Extension Std | F30: No | G30: Reads the New build Standard rates; quantities from the external works area
A31: DM | B31: Demolition only | C31: Refurb & Fit-out Basic | D31: Refurb & Fit-out Std | E31: Refurb & Fit-out High | F31: No
A32: OM | B32: Other or mixed | C32: Per component | D32: Per component | E32: Per component | F32: No | G32: From v4.5: split GIFA by use/type, price each block on its own project type's columns, and sum
A34: ▶ spec_levels | B34: Q2.4 options. The level picks the Basic / Standard / High column on project_types
A35: Level | B35: Description
A36: Basic | B36: Minimum compliance; budget materials; functional finish. Student accommodation, back-of-house, warehouses.
A37: Standard | B37: Good commercial standard; durable mid-range materials. Typical offices, education, general academic space.
A38: High | B38: Flagship/premium; high-end finishes, bespoke joinery, enhanced M&E. Boardrooms, reception, executive, prestige.
A40: ▶ intervention_levels | B40: Level of intervention (Refurbishment and Fit-out only) → band multiplier and design duration (from v4.5)
A41: Level | B41: Name | C41: Band multiplier (m² rates) | D41: Description | E41: Design duration multiplier
A42: 1 | B42: Fabric and finishes only | C42: 0.8 | D42: Decoration, floor/wall finishes, ceilings, fixtures replaced in-place. No M&E work. No walls moved. Lowest cost and shortest programme. | E42: 0.5
A43: 2 | B43: Finishes with minor services | C43: 0.9 | D43: Finishes as above plus light-touch M&E: 2nd fix fixtures, replacement light fittings, sockets and switches. Existing wiring and pipework retained. No new systems. | E43: 0.7
A44: 3 | B44: Full systems replacement | C44: 1 | D44: Complete replacement of heating, plumbing and electrical systems throughout. Same layout, same positions, no structural changes. Building rewired and re-plumbed. Typical full flat or office refurbishment. | E44: 1
A45: 4 | B45: Reconfiguration or full redesign | C45: 1.15 | D45: Layout changes, walls moved or removed, or building stripped to structure and redesigned. Requires architect, structural engineer, building control, possibly planning. Highest cost and longest programme. | E45: 1.3
...

Sheet 4. Scope rules
A1: SCOPE RULES — how the app uses each item (rarely needs changing)
A2: Two tables, each starting at its ▶ marker and ending at the first blank row — to add a row, insert it inside the table. ▶ items: one row per Scope ID. ▶ options: one row per Rate key on '2. Rates'. What each column means is on '1. Instructions'.
A4: ▶ items
A5: Scope ID | B5: Code | C5: Item (for reading) | D5: Group | E5: Section | F5: Options: pick | G5: Quantity rule | H5: Shown on (project type codes) | I5: Pre-ticked on (project type codes) | J5: Relevant building uses (codes) | K5: Other conditions | L5: BCIS element 1 | M5: Share 1 | N5: BCIS element 2 | O5: Share 2 | P5: Replaces old codes
A6: S-0001 | B6: 0.1 | C6: Asbestos removal | D6: 0 Facilitating works | E6: — | F6: One | G6: IF(PT=NB EX, DEMOLISHED, GIFA) | H6: NB EX RF FO EW DM OM | I6: — | J6: ALL | K6: AGE<2000 & PT=RF FO DM → tick | L6: 0.1 | M6: 1 | P6: 0.1
A7: S-0002 | B7: 0.2 | C7: Demolition of existing building | D7: 0 Facilitating works | E7: — | F7: One | G7: DEMOLISHED | H7: NB EX EW DM OM | I7: DM | J7: ALL | L7: 0.2 | M7: 1 | P7: 0.2
A8: S-0003 | B8: 0.3 | C8: Strip-out | D8: 0 Facilitating works | E8: — | F8: One | G8: GIFA | H8: RF FO OM | I8: — | J8: ALL | L8: 0.2 | M8: 1 | P8: 0.5
A9: S-0004 | B9: 0.4 | C9: Contaminated land | D9: 0 Facilitating works | E9: — | F9: One | G9: IF(PT=EW, EXT_AREA, GIFA) | H9: NB EX EW OM | I9: — | J9: ALL | L9: 0.1 | M9: 1 | P9: 0.3
A10: S-0005 | B10: 0.5 | C10: Ground improvement | D10: 0 Facilitating works | E10: — | F10: One | G10: FOOTPRINT | H10: NB EX EW OM | I10: — | J10: ALL | L10: 0.4 | M10: 1 | P10: 0.4
A11: S-0006 | B11: 0.6 | C11: Tree removal | D11: 0 Facilitating works | E11: — | F11: One | G11: ENTER | H11: NB EX EW DM OM | I11: — | J11: ALL | L11: 8.1 | M11: 1 | P11: 0.6
A12: S-0007 | B12: 0.7 | C12: Service diversions | D12: 0 Facilitating works | E12: — | F12: One | G12: IF(PT=EW, EXT_AREA, FOOTPRINT) | H12: NB EX EW DM OM | I12: — | J12: ALL | L12: 0.5 | M12: 1 | P12: 0.7
A13: S-0008 | B13: 1.1 | C13: Foundations | D13: 1 Substructure | E13: — | F13: One | G13: FOOTPRINT | H13: NB EX OM | I13: NB EX | J13: ALL | L13: 1.1 | M13: 1 | P13: 1.1, 1.2
A14: S-0009 | B14: 1.2 | C14: Ground floor slab | D14: 1 Substructure | E14: — | F14: One | G14: FOOTPRINT | H14: NB EX OM | I14: NB EX | J14: ALL | L14: 1.1 | M14: 1 | P14: 1.3
A15: S-0010 | B15: 1.3 | C15: Basement | D15: 1 Substructure | E15: — | F15: One | G15: FOOTPRINT | H15: NB EX OM | I15: — | J15: ALL | L15: 1.1 | M15: 1 | P15: 1.4, 2.9, 2.10
A16: S-0011 | B16: 2.1 | C16: Frame | D16: 2 Superstructure and envelope | E16: Structure | F16: One | G16: GIFA | H16: NB EX OM | I16: NB EX | J16: ALL | L16: 2.1 | M16: 1 | P16: 2.1
A17: S-0012 | B17: 2.2 | C17: Upper floors | D17: 2 Superstructure and envelope | E17: Structure | F17: One | G17: UPPER | H17: NB EX OM | I17: NB EX | J17: ALL | K17: STOREYS<2 → untick | L17: 2.2 | M17: 1 | P17: 2.2
A18: S-0013 | B18: 2.3 | C18: Stairs and ramps | D18: 2 Superstructure and envelope | E18: Structure | F18: One | G18: GIFA | H18: NB EX RF OM | I18: NB EX | J18: ALL | K18: STOREYS<2 → untick | L18: 2.4 | M18: 1 | P18: 2.4
A19: S-0014 | B19: 2.4 | C19: Mezzanine floor | D19: 2 Superstructure and envelope | E19: Structure | F19: One | G19: ENTER | H19: NB EX FO OM | I19: — | J19: OFF EDU RET IND | L19: 2.2 | M19: 1 | P19: 2.12, 6.2
A20: S-0015 | B20: 2.5 | C20: Roof | D20: 2 Superstructure and envelope | E20: Roof and walls | F20: One | G20: FOOTPRINT | H20: NB EX RF OM | I20: NB EX | J20: ALL | L20: 2.3 | M20: 1 | P20: 2.3
A21: S-0016 | B21: 2.6 | C21: External walls | D21: 2 Superstructure and envelope | E21: Roof and walls | F21: One | G21: GIFA | H21: NB EX RF OM | I21: NB EX | J21: ALL | L21: 2.5 | M21: 1 | P21: 2.5
A22: S-0017 | B22: 2.7 | C22: Windows and external doors | D22: 2 Superstructure and envelope | E22: Roof and walls | F22: One | G22: GIFA | H22: NB EX RF OM | I22: NB EX | J22: ALL | L22: 2.6 | M22: 1 | P22: 2.6
A23: S-0018 | B23: 2.8 | C23: Internal walls | D23: 2 Superstructure and envelope | E23: Internal walls and doors | F23: One | G23: IF(USE=IND, IF(PT=NB EX, OFFICES, GIFA), GIFA) | H23: NB EX RF FO OM | I23: NB EX | J23: ALL | L23: 2.7 | M23: 1 | P23: 2.7
A24: S-0019 | B24: 2.9 | C24: Internal doors | D24: 2 Superstructure and envelope | E24: Internal walls and doors | F24: One | G24: IF(USE=IND, IF(PT=NB EX, OFFICES, GIFA), GIFA) | H24: NB EX RF FO OM | I24: NB EX | J24: ALL | L24: 2.8 | M24: 1 | P24: 2.8
A25: S-0020 | B25: 2.10 | C25: Fire stopping | D25: 2 Superstructure and envelope | E25: Internal walls and doors | F25: One | G25: GIFA | H25: EX RF FO OM | I25: — | J25: ALL | L25: 2.7 | M25: 1 | P25: 2.11
A26: S-0021 | B26: 3.1 | C26: Wall finishes | D26: 3 Internal finishes | E26: — | F26: One | G26: IF(USE=IND, IF(PT=NB EX, OFFICES, GIFA), GIFA) | H26: NB EX RF FO OM | I26: NB EX | J26: ALL | L26: 3.1 | M26: 1 | P26: 2.9, 3.1
A27: S-0022 | B27: 3.2 | C27: Floor finishes | D27: 3 Internal finishes | E27: — | F27: One | G27: IF(USE=IND, IF(PT=NB EX, OFFICES, GIFA), GIFA) | H27: NB EX RF FO OM | I27: NB EX | J27: ALL | L27: 3.2 | M27: 1 | P27: 2.9, 3.2
A28: S-0023 | B28: 3.3 | C28: Ceiling finishes | D28: 3 Internal finishes | E28: — | F28: One | G28: IF(USE=IND, IF(PT=NB EX, OFFICES, GIFA), GIFA) | H28: NB EX RF FO OM | I28: NB EX | J28: ALL | L28: 3.3 | M28: 1 | P28: 3.3
A29: S-0024 | B29: 4.1 | C29: Toilets | D29: 4 Toilets, kitchens and fittings | E29: Toilets, bathrooms and kitchens | F29: Several | G29: ROUND(GIFA / r.m2_per_person / r.persons_per_wc, 0) | H29: NB EX RF FO OM | I29: NB EX | J29: OFF EDU HEA RET IND HOS | L29: 5.1 | M29: 0.8 | N29: 2.7 | O29: 0.2 | P29: 4.2-COM, 4.2-HC, 4.2-HP, 4.31-NR, 4.32-HOH, 5.30-NR
A30: S-0025 | B30: 4.2 | C30: Bathrooms and en-suites | D30: 4 Toilets, kitchens and fittings | E30: Toilets, bathrooms and kitchens | F30: One | G30: ROUND(IF(USE=STU, GIFA / r.m2_per_bed, IF(USE=HOS, GIFA / r.m2_per_key, GIFA / r.m2_per_dwelling * r.bathrooms_per_dwelling)), 0) | H30: NB EX RF FO OM | I30: NB EX | J30: RES STU HOS | L30: 5.1 | M30: 1 | P30: 4.2-HG, 4.2-RES, 6.3
A31: S-0026 | B31: 4.3 | C31: Showers | D31: 4 Toilets, kitchens and fittings | E31: Toilets, bathrooms and kitchens | F31: One | G31: ENTER | H31: NB EX RF FO OM | I31: — | J31: OFF EDU HEA RET IND HOS | L31: 5.1 | M31: 1 | P31: 4.41
A32: S-0027 | B32: 4.4 | C32: Kitchens | D32: 4 Toilets, kitchens and fittings | E32: Toilets, bathrooms and kitchens | F32: One | G32: ROUND(IF(USE=RES, GIFA / r.m2_per_dwelling, IF(USE=STU, GIFA / r.m2_per_bed / r.beds_per_kitchen, STOREYS * r.tea_points_per_floor)), 0) | H32: NB EX RF FO OM | I32: NB EX | J32: ALL | L32: 4.2 | M32: 1 | P32: 4.3, 4.3-NR, 4.3-RES, 4.42
A33: S-0028 | B33: 4.5 | C33: Fixed joinery | D33: 4 Toilets, kitchens and fittings | E33: Fittings and furniture | F33: One | G33: GIFA | H33: NB EX RF FO OM | I33: — | J33: ALL | L33: 4.1 | M33: 1 | P33: 4.1
A34: S-0029 | B34: 4.6 | C34: Signage | D34: 4 Toilets, kitchens and fittings | E34: Fittings and furniture | F34: One | G34: IF(USE=IND, IF(PT=NB EX, OFFICES, GIFA), GIFA) | H34: NB EX RF FO OM | I34: NB EX | J34: ALL | L34: 4.4 | M34: 1 | P34: 4.5
A35: S-0030 | B35: 4.7 | C35: AV equipment | D35: 4 Toilets, kitchens and fittings | E35: Fittings and furniture | F35: One | G35: GIFA | H35: NB EX RF FO OM | I35: — | J35: OFF EDU HEA HOS | L35: 5.12 | M35: 1 | P35: 4.22
A36: S-0031 | B36: 4.8 | C36: Loose furniture | D36: 4 Toilets, kitchens and fittings | E36: Fittings and furniture | F36: One | G36: GIFA | H36: NB EX RF FO OM | I36: — | J36: ALL | L36: 4.1 | M36: 1 | P36: 4.6, 4.7, 4.8, 4.9, 4.33
A37: S-0032 | B37: 4.9 | C37: Catering kitchen | D37: 4 Toilets, kitchens and fittings | E37: Specialist equipment | F37: One | G37: GIFA * r.pct_catering | H37: NB EX RF FO OM | I37: — | J37: STU OFF EDU HEA RET IND HOS | L37: 5.2 | M37: 1 | P37: 4.10, 4.11, 4.12, 4.16, 4.34
A38: S-0033 | B38: 4.10 | C38: Laboratory | D38: 4 Toilets, kitchens and fittings | E38: Specialist equipment | F38: One | G38: GIFA * r.pct_lab | H38: NB EX RF FO OM | I38: — | J38: EDU HEA IND | L38: 4.3 | M38: 1 | P38: 4.20, 4.21, 4.36
A39: S-0034 | B39: 4.11 | C39: Clinical | D39: 4 Toilets, kitchens and fittings | E39: Specialist equipment | F39: One | G39: GIFA * r.pct_clinical | H39: NB EX RF FO OM | I39: — | J39: HEA | L39: 4.3 | M39: 1 | P39: 4.19, 4.37
A40: S-0035 | B40: 4.12 | C40: Retail | D40: 4 Toilets, kitchens and fittings | E40: Specialist equipment | F40: One | G40: IF(USE=RET, GIFA, ENTER) | H40: NB EX RF FO OM | I40: — | J40: RET | L40: 4.3 | M40: 1 | P40: 4.24, 4.25, 4.27, 4.35
A41: S-0036 | B41: 4.13 | C41: Warehouse | D41: 4 Toilets, kitchens and fittings | E41: Specialist equipment | F41: One | G41: IF(USE=IND, GIFA, ENTER) | H41: NB EX RF FO OM | I41: — | J41: IND | L41: 4.3 | M41: 1 | P41: 4.13, 4.14, 4.15, 4.38
...
