Workbook

Sheet Instructions
B1: NRM1 ORDER OF COST ESTIMATE TOOL | Estates AI | Version 2.0 | May 2026
B2: RIBA Stage 0–1 Indicative Estimates | Prepared by Nabil Kayali | Base date Q2 2026 | West Midlands default
B4: WHAT'S NEW IN VERSION 2.0
B5: ▸ Mid-point rate architecture — each element now has a single benchmark mid-point (£/m²) with ±spread applied automatically
B6: ▸ Tighter 20-25% spread (Low–High range) replacing the previous wide ranges that were not useful for feasibility reporting
B7: ▸ Three specification levels per project type — Basic, Standard, High Spec — each on a separate tab
B8: ▸ Rates Reference Table tab — all benchmark mid-point rates in one place; update here and all tabs recalculate
B9: ▸ BCIS-traceable structure — rate cells reference a named source column; when a BCIS subscription is obtained, update the Rates Table
B11: SPECIFICATION LEVELS — WHICH TAB TO USE
B12: Level 1 — Basic / Maintenance: Like-for-like replacement, redecoration, basic M&E refresh. No layout change. Functional finish only.
B13: Level 2 — Standard / Cat A–B: Modified layout, new M&E distribution, Cat A or Cat B office/teaching finish. Most university estates projects.
B14: Level 3 — High Spec / Specialist: Flagship, lab, healthcare, or bespoke. Heavy M&E, specialist fit-out, feature finishes. Premium.
... B45: All figures are LOW–HIGH ranges only. No single-point estimates are shown. Rates should be updated against BCIS data before formal use.

Sheet Rates Reference Table
A1: RATES REFERENCE TABLE — Mid-point £/m² GIFA Benchmark Rates | Q2 2026 | UK National Mean | Update this table to refresh all estimate tabs
A2: Source: Sense-checked against RICS/BCIS published ranges Q4 2025–Q2 2026, Cushman & Wakefield UK Fit-Out Guide 2025, RateQS benchmarks Nov 2025. All rates are mid-point estimates at UK national mean. Apply BCIS regional factor in estimate tabs. Update quarterly when BCIS subscription is available.
A4: Grp | B4: Sub | C4: Element / Description | D4: Unit | E4: Rfb Basic | F4: Rfb Standard | G4: Rfb High Spec | H4: New Build Standard | I4: New Build High Spec | J4: Extension Standard | K4: Extension High Spec | L4: External Works Only | M4: Notes / Rate Driver
A5: GROUP 0 — FACILITATING WORKS — Include if demolition, known asbestos, or brownfield site identified in questionnaire
A6: 0 | B6: 0.1 | C6: Toxic/hazardous material removal | D6: Item | E6: 15 | F6: 25 | G6: 40 | H6: 10 | I6: 20 | J6: 10 | K6: 20 | L6: 0 | M6: Asbestos; increase if confirmed present (refurb/demo only)
A7: 0 | B7: 0.2 | C7: Demolition & structural alterations | D7: Item | E7: 20 | F7: 35 | G7: 55 | H7: 15 | I7: 25 | J7: 20 | K7: 35 | L7: 5 | M7: Selective or full demolition; structural openings
A8: 0 | B8: 0.3 | C8: Contaminated land remediation | D8: Item | E8: 5 | F8: 10 | G8: 20 | H8: 10 | I8: 20 | J8: 5 | K8: 15 | L8: 10 | M8: Brownfield/contaminated; specialist quote needed
A9: 0 | B9: 0.4 | C9: Ground stabilisation | D9: Item | E9: 5 | F9: 8 | G9: 15 | H9: 8 | I9: 15 | J9: 5 | K9: 12 | L9: 5 | M9: Underpinning/piling if ground risk identified
A10: GROUP 1 — SUBSTRUCTURE — New build and extension only; always exclude for pure refurb/fit-out
A11: 1 | B11: 1.1 | C11: Standard foundations (strip/pad) | D11: m² | E11: 0 | F11: 0 | G11: 0 | H11: 55 | I11: 80 | J11: 55 | K11: 80 | L11: 0 | M11: New build only; included in Group 7 rate for extensions
A12: 1 | B12: 1.2 | C12: Specialist foundations (piled) | D12: m² | E12: 0 | F12: 0 | G12: 0 | H12: 40 | I12: 60 | J12: 40 | K12: 60 | L12: 0 | M12: Poor ground conditions; trigger from GI report
A13: 1 | B13: 1.3 | C13: Lowest floor construction (slab) | D13: m² | E13: 0 | F13: 0 | G13: 0 | H13: 35 | I13: 55 | J13: 35 | K13: 55 | L13: 0 | M13: Ground bearing or suspended; inc DPM and insulation
A14: 1 | B14: 1.4 | C14: Basement excavation & structure | D14: Item | E14: 0 | F14: 0 | G14: 0 | H14: 80 | I14: 150 | J14: 80 | K14: 150 | L14: 0 | M14: High uncertainty; specialist estimate recommended
A15: GROUP 2 — SUPERSTRUCTURE — Core element for new build; partial inclusion for extension/refurb with structural alterations
A16: 2 | B16: 2.1 | C16: Structural frame | D16: m² | E16: 0 | F16: 20 | G16: 40 | H16: 150 | I16: 220 | J16: 130 | K16: 200 | L16: 0 | M16: Steel/concrete/timber; new build or major extensions only
A17: 2 | B17: 2.2 | C17: Upper floors | D17: m² | E17: 0 | F17: 15 | G17: 30 | H17: 65 | I17: 95 | J17: 65 | K17: 95 | L17: 0 | M17: New build or added floors; inc topping and insulation
A18: 2 | B18: 2.3 | C18: Roof structure & covering | D18: m² | E18: 35 | F18: 55 | G18: 90 | H18: 75 | I18: 120 | J18: 75 | K18: 120 | L18: 0 | M18: New or replacement; inc insulation, waterproofing, rainwater
A19: 2 | B19: 2.4 | C19: Stairs & ramps | D19: Item | E19: 10 | F19: 15 | G19: 25 | H19: 20 | I19: 35 | J19: 20 | K19: 35 | L19: 0 | M19: RC, steel or timber; accessibility ramps
A20: 2 | B20: 2.5 | C20: External walls & facade | D20: m² | E20: 30 | F20: 60 | G20: 110 | H20: 200 | I20: 320 | J20: 180 | K20: 280 | L20: 0 | M20: Masonry/cladding; refurb = overcladding or repair only
A21: 2 | B21: 2.6 | C21: Windows & external doors | D21: m² | E21: 80 | F21: 130 | G21: 200 | H21: 100 | I21: 160 | J21: 90 | K21: 150 | L21: 0 | M21: uPVC (low) to aluminium curtain wall (high)
A22: 2 | B22: 2.7 | C22: Internal walls & partitions | D22: m² | E22: 20 | F22: 35 | G22: 60 | H22: 30 | I22: 50 | J22: 25 | K22: 45 | L22: 0 | M22: Blockwork, drywall or glazed; do not double-count Grp 3
A23: 2 | B23: 2.8 | C23: Internal doors & ironmongery | D23: Nr | E23: 15 | F23: 25 | G23: 40 | H23: 20 | I23: 35 | J23: 18 | K23: 30 | L23: 0 | M23: Fire-rated at upper range; standard at lower
A24: GROUP 3 — INTERNAL FINISHES ★ ALWAYS INCLUDED — NEVER excluded — every project has internal finishes to some level
A25: 3 | B25: 3.1 | C25: Wall finishes | D25: m² | E25: 15 | F25: 35 | G25: 75 | H25: 25 | I25: 55 | J25: 20 | K25: 50 | L25: 0 | M25: Emulsion (low) → specialist tiling/feature panelling (high)
A26: 3 | B26: 3.2 | C26: Floor finishes | D26: m² | E26: 20 | F26: 55 | G26: 130 | H26: 30 | I26: 80 | J26: 25 | K26: 70 | L26: 0 | M26: Vinyl/carpet (low) → stone/raised access floor (high)
A27: 3 | B27: 3.3 | C27: Ceiling finishes | D27: m² | E27: 10 | F27: 30 | G27: 65 | H27: 15 | I27: 45 | J27: 12 | K27: 40 | L27: 0 | M27: Emulsion (low) → bespoke acoustic ceiling system (high)
A28: GROUP 4 — FITTINGS, FURNISHINGS & EQUIPMENT — Include if joinery, kitchens, toilets or specialist fit-out selected in Q2.2
A29: 4 | B29: 4.1 | C29: General fittings & built-in joinery | D29: Item | E29: 10 | F29: 30 | G29: 80 | H29: 15 | I29: 50 | J29: 10 | K29: 40 | L29: 0 | M29: Reception desks, shelving, built-in furniture
A30: 4 | B30: 4.2 | C30: Sanitary fittings & toilet fit-out | D30: Nr | E30: 8 | F30: 18 | G30: 35 | H30: 10 | I30: 22 | J30: 8 | K30: 18 | L30: 0 | M30: WC packs; uplift for accessible/changing facilities
A31: 4 | B31: 4.3 | C31: Kitchen / break-out area | D31: Item | E31: 5 | F31: 15 | G31: 35 | H31: 8 | I31: 20 | J31: 5 | K31: 15 | L31: 0 | M31: Fitted units, worktops, appliances
A32: 4 | B32: 4.4 | C32: Specialist equipment (lab/AV/med) | D32: Item | E32: 0 | F32: 10 | G32: 80 | H32: 5 | I32: 60 | J32: 0 | K32: 40 | L32: 0 | M32: Laboratory, medical, AV; confirm with specialist
A33: GROUP 5 — MECHANICAL & ELECTRICAL SERVICES ★ KEY ELEMENT — Always price separately — never bundle into superstructure rate
A34: 5 | B34: 5.1 | C34: Sanitary plumbing (1st & 2nd fix) | D34: m² | E34: 15 | F34: 35 | G34: 65 | H34: 25 | I34: 50 | J34: 20 | K34: 45 | L34: 0 | M34: HWS, cold water, drainage connections
A35: 5 | B35: 5.2 | C35: Heating & hot water (LTHW/heat pump) | D35: m² | E35: 25 | F35: 50 | G35: 90 | H35: 35 | I35: 70 | J35: 30 | K35: 65 | L35: 0 | M35: LTHW system or heat pump; include buffer vessel
A36: 5 | B36: 5.3 | C36: Ventilation & air handling | D36: m² | E36: 20 | F36: 45 | G36: 90 | H36: 30 | I36: 70 | J36: 25 | K36: 60 | L36: 0 | M36: MVHR/AHU; uplift for lab/healthcare extract (+50-100%)
A37: 5 | B37: 5.4 | C37: Air conditioning & cooling | D37: m² | E37: 0 | F37: 30 | G37: 70 | H37: 15 | I37: 55 | J37: 10 | K37: 45 | L37: 0 | M37: VRF/splits; omit if not in scope
A38: 5 | B38: 5.5 | C38: Gas installation | D38: Item | E38: 5 | F38: 10 | G38: 15 | H38: 8 | I38: 15 | J38: 5 | K38: 10 | L38: 0 | M38: Omit if all-electric; confirm with utility
A39: 5 | B39: 5.6 | C39: Sprinkler / fire suppression | D39: m² | E39: 0 | F39: 15 | G39: 30 | H39: 10 | I39: 25 | J39: 5 | K39: 20 | L39: 0 | M39: >18m height or insurer requirement
A40: 5 | B40: 5.7 | C40: Electrical distribution & switchgear | D40: m² | E40: 15 | F40: 30 | G40: 55 | H40: 20 | I40: 45 | J40: 15 | K40: 40 | L40: 0 | M40: LV panels, distribution boards, earthing, containment
A41: 5 | B41: 5.8 | C41: Electrical wiring (1st & 2nd fix) | D41: m² | E41: 20 | F41: 40 | G41: 75 | H41: 30 | I41: 60 | J41: 25 | K41: 55 | L41: 0 | M41: All power and lighting circuits; inc containment
...

Sheet Rfb – Basic
A1: NRM1 ESTIMATE — REFURB / FIT-OUT — BASIC / MAINTENANCE
A2: Spec level: Like-for-like replacement, redecoration, basic M&E refresh. No layout changes. | RIBA Stage 0–1 indicative only | Base date Q2 2026
A4: Project Type: | B4: Refurb / Fit-Out | D4: Spec Level: | E4: Basic / Maintenance | G4: Region: | H4: West Midlands
A5: GIFA (m²) ▼ update: | B5: 500 | D5: BCIS Location Factor ▼: | E5: 0.94 | G5: Spread ±% ▼: | H5: 0.22
A7: Grp | B7: Sub | C7: Element / Description | D7: Unit | E7: Mid-Point £/m² | F7: Low £/m² | G7: High £/m² | H7: Total LOW (£) | I7: Total HIGH (£) | J7: Notes / Rate Driver
A8: GROUP 0 — FACILITATING WORKS
A9: 0 | B9: 0.1 | C9: Toxic/hazardous material removal | D9: Item | E9: =IFERROR('Rates Reference Table'!E6*$E$5,0) -> 14.1 | F9: =IFERROR(E9*(1-$H$5/2),0) -> 12.549 | G9: =IFERROR(E9*(1+$H$5/2),0) -> 15.651 | H9: =IFERROR(F9*$B$5,0) -> 6274.5 | I9: =IFERROR(G9*$B$5,0) -> 7825.5 | J9: Asbestos; increase if confirmed present (refurb/demo only)
A10: 0 | B10: 0.2 | C10: Demolition & structural alterations | D10: Item | E10: =IFERROR('Rates Reference Table'!E7*$E$5,0) -> 18.8 | F10: =IFERROR(E10*(1-$H$5/2),0) -> 16.732 | G10: =IFERROR(E10*(1+$H$5/2),0) -> 20.868 | H10: =IFERROR(F10*$B$5,0) -> 8366 | I10: =IFERROR(G10*$B$5,0) -> 10434 | J10: Selective or full demolition; structural openings
A11: 0 | B11: 0.3 | C11: Contaminated land remediation | D11: Item | E11: =IFERROR('Rates Reference Table'!E8*$E$5,0) -> 4.7 | F11: =IFERROR(E11*(1-$H$5/2),0) -> 4.183 | G11: =IFERROR(E11*(1+$H$5/2),0) -> 5.217 | H11: =IFERROR(F11*$B$5,0) -> 2091.5 | I11: =IFERROR(G11*$B$5,0) -> 2608.5 | J11: Brownfield/contaminated; specialist quote needed
A12: 0 | B12: 0.4 | C12: Ground stabilisation | D12: Item | E12: =IFERROR('Rates Reference Table'!E9*$E$5,0) -> 4.7 | F12: =IFERROR(E12*(1-$H$5/2),0) -> 4.183 | G12: =IFERROR(E12*(1+$H$5/2),0) -> 5.217 | H12: =IFERROR(F12*$B$5,0) -> 2091.5 | I12: =IFERROR(G12*$B$5,0) -> 2608.5 | J12: Underpinning/piling if ground risk identified
A13: GROUP 1 — SUBSTRUCTURE
A14: 1 | B14: 1.1 | C14: Standard foundations (strip/pad) | D14: m² | E14: EXCLUDED | F14: EXCLUDED | G14: EXCLUDED | H14: 0 | I14: 0 | J14: New build only; included in Group 7 rate for extensions
A15: 1 | B15: 1.2 | C15: Specialist foundations (piled) | D15: m² | E15: EXCLUDED | F15: EXCLUDED | G15: EXCLUDED | H15: 0 | I15: 0 | J15: Poor ground conditions; trigger from GI report
A16: 1 | B16: 1.3 | C16: Lowest floor construction (slab) | D16: m² | E16: EXCLUDED | F16: EXCLUDED | G16: EXCLUDED | H16: 0 | I16: 0 | J16: Ground bearing or suspended; inc DPM and insulation
A17: 1 | B17: 1.4 | C17: Basement excavation & structure | D17: Item | E17: EXCLUDED | F17: EXCLUDED | G17: EXCLUDED | H17: 0 | I17: 0 | J17: High uncertainty; specialist estimate recommended
A18: GROUP 2 — SUPERSTRUCTURE
A19: 2 | B19: 2.1 | C19: Structural frame | D19: m² | E19: =IFERROR('Rates Reference Table'!E16*$E$5,0) -> 0 | F19: =IFERROR(E19*(1-$H$5/2),0) -> 0 | G19: =IFERROR(E19*(1+$H$5/2),0) -> 0 | H19: =IFERROR(F19*$B$5,0) -> 0 | I19: =IFERROR(G19*$B$5,0) -> 0 | J19: Steel/concrete/timber; new build or major extensions only
A20: 2 | B20: 2.2 | C20: Upper floors | D20: m² | E20: =IFERROR('Rates Reference Table'!E17*$E$5,0) -> 0 | F20: =IFERROR(E20*(1-$H$5/2),0) -> 0 | G20: =IFERROR(E20*(1+$H$5/2),0) -> 0 | H20: =IFERROR(F20*$B$5,0) -> 0 | I20: =IFERROR(G20*$B$5,0) -> 0 | J20: New build or added floors; inc topping and insulation
A21: 2 | B21: 2.3 | C21: Roof structure & covering | D21: m² | E21: =IFERROR('Rates Reference Table'!E18*$E$5,0) -> 32.9 | F21: =IFERROR(E21*(1-$H$5/2),0) -> 29.281 | G21: =IFERROR(E21*(1+$H$5/2),0) -> 36.519 | H21: =IFERROR(F21*$B$5,0) -> 14640.5 | I21: =IFERROR(G21*$B$5,0) -> 18259.5 | J21: New or replacement; inc insulation, waterproofing, rainwater
A22: 2 | B22: 2.4 | C22: Stairs & ramps | D22: Item | E22: =IFERROR('Rates Reference Table'!E19*$E$5,0) -> 9.4 | F22: =IFERROR(E22*(1-$H$5/2),0) -> 8.366 | G22: =IFERROR(E22*(1+$H$5/2),0) -> 10.434 | H22: =IFERROR(F22*$B$5,0) -> 4183 | I22: =IFERROR(G22*$B$5,0) -> 5217 | J22: RC, steel or timber; accessibility ramps
A23: 2 | B23: 2.5 | C23: External walls & facade | D23: m² | E23: =IFERROR('Rates Reference Table'!E20*$E$5,0) -> 28.2 | F23: =IFERROR(E23*(1-$H$5/2),0) -> 25.098 | G23: =IFERROR(E23*(1+$H$5/2),0) -> 31.302 | H23: =IFERROR(F23*$B$5,0) -> 12549 | I23: =IFERROR(G23*$B$5,0) -> 15651 | J23: Masonry/cladding; refurb = overcladding or repair only
A24: 2 | B24: 2.6 | C24: Windows & external doors | D24: m² | E24: =IFERROR('Rates Reference Table'!E21*$E$5,0) -> 75.2 | F24: =IFERROR(E24*(1-$H$5/2),0) -> 66.928 | G24: =IFERROR(E24*(1+$H$5/2),0) -> 83.472 | H24: =IFERROR(F24*$B$5,0) -> 33464 | I24: =IFERROR(G24*$B$5,0) -> 41736 | J24: uPVC (low) to aluminium curtain wall (high)
A25: 2 | B25: 2.7 | C25: Internal walls & partitions | D25: m² | E25: =IFERROR('Rates Reference Table'!E22*$E$5,0) -> 18.8 | F25: =IFERROR(E25*(1-$H$5/2),0) -> 16.732 | G25: =IFERROR(E25*(1+$H$5/2),0) -> 20.868 | H25: =IFERROR(F25*$B$5,0) -> 8366 | I25: =IFERROR(G25*$B$5,0) -> 10434 | J25: Blockwork, drywall or glazed; do not double-count Grp 3
A26: 2 | B26: 2.8 | C26: Internal doors & ironmongery | D26: Nr | E26: =IFERROR('Rates Reference Table'!E23*$E$5,0) -> 14.1 | F26: =IFERROR(E26*(1-$H$5/2),0) -> 12.549 | G26: =IFERROR(E26*(1+$H$5/2),0) -> 15.651 | H26: =IFERROR(F26*$B$5,0) -> 6274.5 | I26: =IFERROR(G26*$B$5,0) -> 7825.5 | J26: Fire-rated at upper range; standard at lower
A27: GROUP 3 — INTERNAL FINISHES ★ ALWAYS INCLUDED
A28: 3 | B28: 3.1 | C28: Wall finishes | D28: m² | E28: =IFERROR('Rates Reference Table'!E25*$E$5,0) -> 14.1 | F28: =IFERROR(E28*(1-$H$5/2),0) -> 12.549 | G28: =IFERROR(E28*(1+$H$5/2),0) -> 15.651 | H28: =IFERROR(F28*$B$5,0) -> 6274.5 | I28: =IFERROR(G28*$B$5,0) -> 7825.5 | J28: Emulsion (low) → specialist tiling/feature panelling (high)
A29: 3 | B29: 3.2 | C29: Floor finishes | D29: m² | E29: =IFERROR('Rates Reference Table'!E26*$E$5,0) -> 18.8 | F29: =IFERROR(E29*(1-$H$5/2),0) -> 16.732 | G29: =IFERROR(E29*(1+$H$5/2),0) -> 20.868 | H29: =IFERROR(F29*$B$5,0) -> 8366 | I29: =IFERROR(G29*$B$5,0) -> 10434 | J29: Vinyl/carpet (low) → stone/raised access floor (high)
A30: 3 | B30: 3.3 | C30: Ceiling finishes | D30: m² | E30: =IFERROR('Rates Reference Table'!E27*$E$5,0) -> 9.4 | F30: =IFERROR(E30*(1-$H$5/2),0) -> 8.366 | G30: =IFERROR(E30*(1+$H$5/2),0) -> 10.434 | H30: =IFERROR(F30*$B$5,0) -> 4183 | I30: =IFERROR(G30*$B$5,0) -> 5217 | J30: Emulsion (low) → bespoke acoustic ceiling system (high)
A31: GROUP 4 — FITTINGS, FURNISHINGS & EQUIPMENT
A32: 4 | B32: 4.1 | C32: General fittings & built-in joinery | D32: Item | E32: =IFERROR('Rates Reference Table'!E29*$E$5,0) -> 9.4 | F32: =IFERROR(E32*(1-$H$5/2),0) -> 8.366 | G32: =IFERROR(E32*(1+$H$5/2),0) -> 10.434 | H32: =IFERROR(F32*$B$5,0) -> 4183 | I32: =IFERROR(G32*$B$5,0) -> 5217 | J32: Reception desks, shelving, built-in furniture
A33: 4 | B33: 4.2 | C33: Sanitary fittings & toilet fit-out | D33: Nr | E33: =IFERROR('Rates Reference Table'!E30*$E$5,0) -> 7.52 | F33: =IFERROR(E33*(1-$H$5/2),0) -> 6.6928 | G33: =IFERROR(E33*(1+$H$5/2),0) -> 8.3472 | H33: =IFERROR(F33*$B$5,0) -> 3346.4 | I33: =IFERROR(G33*$B$5,0) -> 4173.6 | J33: WC packs; uplift for accessible/changing facilities
A34: 4 | B34: 4.3 | C34: Kitchen / break-out area | D34: Item | E34: =IFERROR('Rates Reference Table'!E31*$E$5,0) -> 4.7 | F34: =IFERROR(E34*(1-$H$5/2),0) -> 4.183 | G34: =IFERROR(E34*(1+$H$5/2),0) -> 5.217 | H34: =IFERROR(F34*$B$5,0) -> 2091.5 | I34: =IFERROR(G34*$B$5,0) -> 2608.5 | J34: Fitted units, worktops, appliances
A35: 4 | B35: 4.4 | C35: Specialist equipment (lab/AV/med) | D35: Item | E35: =IFERROR('Rates Reference Table'!E32*$E$5,0) -> 0 | F35: =IFERROR(E35*(1-$H$5/2),0) -> 0 | G35: =IFERROR(E35*(1+$H$5/2),0) -> 0 | H35: =IFERROR(F35*$B$5,0) -> 0 | I35: =IFERROR(G35*$B$5,0) -> 0 | J35: Laboratory, medical, AV; confirm with specialist
A36: GROUP 5 — MECHANICAL & ELECTRICAL SERVICES ★ KEY ELEMENT
A37: 5 | B37: 5.1 | C37: Sanitary plumbing (1st & 2nd fix) | D37: m² | E37: =IFERROR('Rates Reference Table'!E34*$E$5,0) -> 14.1 | F37: =IFERROR(E37*(1-$H$5/2),0) -> 12.549 | G37: =IFERROR(E37*(1+$H$5/2),0) -> 15.651 | H37: =IFERROR(F37*$B$5,0) -> 6274.5 | I37: =IFERROR(G37*$B$5,0) -> 7825.5 | J37: HWS, cold water, drainage connections
A38: 5 | B38: 5.2 | C38: Heating & hot water (LTHW/heat pump) | D38: m² | E38: =IFERROR('Rates Reference Table'!E35*$E$5,0) -> 23.5 | F38: =IFERROR(E38*(1-$H$5/2),0) -> 20.915 | G38: =IFERROR(E38*(1+$H$5/2),0) -> 26.085 | H38: =IFERROR(F38*$B$5,0) -> 10457.5 | I38: =IFERROR(G38*$B$5,0) -> 13042.5 | J38: LTHW system or heat pump; include buffer vessel
A39: 5 | B39: 5.3 | C39: Ventilation & air handling | D39: m² | E39: =IFERROR('Rates Reference Table'!E36*$E$5,0) -> 18.8 | F39: =IFERROR(E39*(1-$H$5/2),0) -> 16.732 | G39: =IFERROR(E39*(1+$H$5/2),0) -> 20.868 | H39: =IFERROR(F39*$B$5,0) -> 8366 | I39: =IFERROR(G39*$B$5,0) -> 10434 | J39: MVHR/AHU; uplift for lab/healthcare extract (+50-100%)
A40: 5 | B40: 5.4 | C40: Air conditioning & cooling | D40: m² | E40: =IFERROR('Rates Reference Table'!E37*$E$5,0) -> 0 | F40: =IFERROR(E40*(1-$H$5/2),0) -> 0 | G40: =IFERROR(E40*(1+$H$5/2),0) -> 0 | H40: =IFERROR(F40*$B$5,0) -> 0 | I40: =IFERROR(G40*$B$5,0) -> 0 | J40: VRF/splits; omit if not in scope
A41: 5 | B41: 5.5 | C41: Gas installation | D41: Item | E41: =IFERROR('Rates Reference Table'!E38*$E$5,0) -> 4.7 | F41: =IFERROR(E41*(1-$H$5/2),0) -> 4.183 | G41: =IFERROR(E41*(1+$H$5/2),0) -> 5.217 | H41: =IFERROR(F41*$B$5,0) -> 2091.5 | I41: =IFERROR(G41*$B$5,0) -> 2608.5 | J41: Omit if all-electric; confirm with utility
A42: 5 | B42: 5.6 | C42: Sprinkler / fire suppression | D42: m² | E42: =IFERROR('Rates Reference Table'!E39*$E$5,0) -> 0 | F42: =IFERROR(E42*(1-$H$5/2),0) -> 0 | G42: =IFERROR(E42*(1+$H$5/2),0) -> 0 | H42: =IFERROR(F42*$B$5,0) -> 0 | I42: =IFERROR(G42*$B$5,0) -> 0 | J42: >18m height or insurer requirement
...

Sheet Rfb – Standard
A1: NRM1 ESTIMATE — REFURB / FIT-OUT — STANDARD / CAT A–B
A2: Spec level: Modified layout, new M&E distribution, Cat A/B office or teaching space finish. | RIBA Stage 0–1 indicative only | Base date Q2 2026
A4: Project Type: | B4: Refurb / Fit-Out | D4: Spec Level: | E4: Standard / Cat A–B | G4: Region: | H4: West Midlands
A5: GIFA (m²) ▼ update: | B5: 500 | D5: BCIS Location Factor ▼: | E5: 0.94 | G5: Spread ±% ▼: | H5: 0.22
A7: Grp | B7: Sub | C7: Element / Description | D7: Unit | E7: Mid-Point £/m² | F7: Low £/m² | G7: High £/m² | H7: Total LOW (£) | I7: Total HIGH (£) | J7: Notes / Rate Driver
A8: GROUP 0 — FACILITATING WORKS
A9: 0 | B9: 0.1 | C9: Toxic/hazardous material removal | D9: Item | E9: =IFERROR('Rates Reference Table'!F6*$E$5,0) -> 23.5 | F9: =IFERROR(E9*(1-$H$5/2),0) -> 20.915 | G9: =IFERROR(E9*(1+$H$5/2),0) -> 26.085 | H9: =IFERROR(F9*$B$5,0) -> 10457.5 | I9: =IFERROR(G9*$B$5,0) -> 13042.5 | J9: Asbestos; increase if confirmed present (refurb/demo only)
A10: 0 | B10: 0.2 | C10: Demolition & structural alterations | D10: Item | E10: =IFERROR('Rates Reference Table'!F7*$E$5,0) -> 32.9 | F10: =IFERROR(E10*(1-$H$5/2),0) -> 29.281 | G10: =IFERROR(E10*(1+$H$5/2),0) -> 36.519 | H10: =IFERROR(F10*$B$5,0) -> 14640.5 | I10: =IFERROR(G10*$B$5,0) -> 18259.5 | J10: Selective or full demolition; structural openings
A11: 0 | B11: 0.3 | C11: Contaminated land remediation | D11: Item | E11: =IFERROR('Rates Reference Table'!F8*$E$5,0) -> 9.4 | F11: =IFERROR(E11*(1-$H$5/2),0) -> 8.366 | G11: =IFERROR(E11*(1+$H$5/2),0) -> 10.434 | H11: =IFERROR(F11*$B$5,0) -> 4183 | I11: =IFERROR(G11*$B$5,0) -> 5217 | J11: Brownfield/contaminated; specialist quote needed
A12: 0 | B12: 0.4 | C12: Ground stabilisation | D12: Item | E12: =IFERROR('Rates Reference Table'!F9*$E$5,0) -> 7.52 | F12: =IFERROR(E12*(1-$H$5/2),0) -> 6.6928 | G12: =IFERROR(E12*(1+$H$5/2),0) -> 8.3472 | H12: =IFERROR(F12*$B$5,0) -> 3346.4 | I12: =IFERROR(G12*$B$5,0) -> 4173.6 | J12: Underpinning/piling if ground risk identified
A13: GROUP 1 — SUBSTRUCTURE
A14: 1 | B14: 1.1 | C14: Standard foundations (strip/pad) | D14: m² | E14: EXCLUDED | F14: EXCLUDED | G14: EXCLUDED | H14: 0 | I14: 0 | J14: New build only; included in Group 7 rate for extensions
A15: 1 | B15: 1.2 | C15: Specialist foundations (piled) | D15: m² | E15: EXCLUDED | F15: EXCLUDED | G15: EXCLUDED | H15: 0 | I15: 0 | J15: Poor ground conditions; trigger from GI report
A16: 1 | B16: 1.3 | C16: Lowest floor construction (slab) | D16: m² | E16: EXCLUDED | F16: EXCLUDED | G16: EXCLUDED | H16: 0 | I16: 0 | J16: Ground bearing or suspended; inc DPM and insulation
A17: 1 | B17: 1.4 | C17: Basement excavation & structure | D17: Item | E17: EXCLUDED | F17: EXCLUDED | G17: EXCLUDED | H17: 0 | I17: 0 | J17: High uncertainty; specialist estimate recommended
A18: GROUP 2 — SUPERSTRUCTURE
A19: 2 | B19: 2.1 | C19: Structural frame | D19: m² | E19: =IFERROR('Rates Reference Table'!F16*$E$5,0) -> 18.8 | F19: =IFERROR(E19*(1-$H$5/2),0) -> 16.732 | G19: =IFERROR(E19*(1+$H$5/2),0) -> 20.868 | H19: =IFERROR(F19*$B$5,0) -> 8366 | I19: =IFERROR(G19*$B$5,0) -> 10434 | J19: Steel/concrete/timber; new build or major extensions only
A20: 2 | B20: 2.2 | C20: Upper floors | D20: m² | E20: =IFERROR('Rates Reference Table'!F17*$E$5,0) -> 14.1 | F20: =IFERROR(E20*(1-$H$5/2),0) -> 12.549 | G20: =IFERROR(E20*(1+$H$5/2),0) -> 15.651 | H20: =IFERROR(F20*$B$5,0) -> 6274.5 | I20: =IFERROR(G20*$B$5,0) -> 7825.5 | J20: New build or added floors; inc topping and insulation
A21: 2 | B21: 2.3 | C21: Roof structure & covering | D21: m² | E21: =IFERROR('Rates Reference Table'!F18*$E$5,0) -> 51.7 | F21: =IFERROR(E21*(1-$H$5/2),0) -> 46.013 | G21: =IFERROR(E21*(1+$H$5/2),0) -> 57.387 | H21: =IFERROR(F21*$B$5,0) -> 23006.5 | I21: =IFERROR(G21*$B$5,0) -> 28693.5 | J21: New or replacement; inc insulation, waterproofing, rainwater
A22: 2 | B22: 2.4 | C22: Stairs & ramps | D22: Item | E22: =IFERROR('Rates Reference Table'!F19*$E$5,0) -> 14.1 | F22: =IFERROR(E22*(1-$H$5/2),0) -> 12.549 | G22: =IFERROR(E22*(1+$H$5/2),0) -> 15.651 | H22: =IFERROR(F22*$B$5,0) -> 6274.5 | I22: =IFERROR(G22*$B$5,0) -> 7825.5 | J22: RC, steel or timber; accessibility ramps
A23: 2 | B23: 2.5 | C23: External walls & facade | D23: m² | E23: =IFERROR('Rates Reference Table'!F20*$E$5,0) -> 56.4 | F23: =IFERROR(E23*(1-$H$5/2),0) -> 50.196 | G23: =IFERROR(E23*(1+$H$5/2),0) -> 62.604 | H23: =IFERROR(F23*$B$5,0) -> 25098 | I23: =IFERROR(G23*$B$5,0) -> 31302 | J23: Masonry/cladding; refurb = overcladding or repair only
A24: 2 | B24: 2.6 | C24: Windows & external doors | D24: m² | E24: =IFERROR('Rates Reference Table'!F21*$E$5,0) -> 122.2 | F24: =IFERROR(E24*(1-$H$5/2),0) -> 108.758 | G24: =IFERROR(E24*(1+$H$5/2),0) -> 135.642 | H24: =IFERROR(F24*$B$5,0) -> 54379 | I24: =IFERROR(G24*$B$5,0) -> 67821 | J24: uPVC (low) to aluminium curtain wall (high)
A25: 2 | B25: 2.7 | C25: Internal walls & partitions | D25: m² | E25: =IFERROR('Rates Reference Table'!F22*$E$5,0) -> 32.9 | F25: =IFERROR(E25*(1-$H$5/2),0) -> 29.281 | G25: =IFERROR(E25*(1+$H$5/2),0) -> 36.519 | H25: =IFERROR(F25*$B$5,0) -> 14640.5 | I25: =IFERROR(G25*$B$5,0) -> 18259.5 | J25: Blockwork, drywall or glazed; do not double-count Grp 3
A26: 2 | B26: 2.8 | C26: Internal doors & ironmongery | D26: Nr | E26: =IFERROR('Rates Reference Table'!F23*$E$5,0) -> 23.5 | F26: =IFERROR(E26*(1-$H$5/2),0) -> 20.915 | G26: =IFERROR(E26*(1+$H$5/2),0) -> 26.085 | H26: =IFERROR(F26*$B$5,0) -> 10457.5 | I26: =IFERROR(G26*$B$5,0) -> 13042.5 | J26: Fire-rated at upper range; standard at lower
A27: GROUP 3 — INTERNAL FINISHES ★ ALWAYS INCLUDED
A28: 3 | B28: 3.1 | C28: Wall finishes | D28: m² | E28: =IFERROR('Rates Reference Table'!F25*$E$5,0) -> 32.9 | F28: =IFERROR(E28*(1-$H$5/2),0) -> 29.281 | G28: =IFERROR(E28*(1+$H$5/2),0) -> 36.519 | H28: =IFERROR(F28*$B$5,0) -> 14640.5 | I28: =IFERROR(G28*$B$5,0) -> 18259.5 | J28: Emulsion (low) → specialist tiling/feature panelling (high)
A29: 3 | B29: 3.2 | C29: Floor finishes | D29: m² | E29: =IFERROR('Rates Reference Table'!F26*$E$5,0) -> 51.7 | F29: =IFERROR(E29*(1-$H$5/2),0) -> 46.013 | G29: =IFERROR(E29*(1+$H$5/2),0) -> 57.387 | H29: =IFERROR(F29*$B$5,0) -> 23006.5 | I29: =IFERROR(G29*$B$5,0) -> 28693.5 | J29: Vinyl/carpet (low) → stone/raised access floor (high)
A30: 3 | B30: 3.3 | C30: Ceiling finishes | D30: m² | E30: =IFERROR('Rates Reference Table'!F27*$E$5,0) -> 28.2 | F30: =IFERROR(E30*(1-$H$5/2),0) -> 25.098 | G30: =IFERROR(E30*(1+$H$5/2),0) -> 31.302 | H30: =IFERROR(F30*$B$5,0) -> 12549 | I30: =IFERROR(G30*$B$5,0) -> 15651 | J30: Emulsion (low) → bespoke acoustic ceiling system (high)
A31: GROUP 4 — FITTINGS, FURNISHINGS & EQUIPMENT
A32: 4 | B32: 4.1 | C32: General fittings & built-in joinery | D32: Item | E32: =IFERROR('Rates Reference Table'!F29*$E$5,0) -> 28.2 | F32: =IFERROR(E32*(1-$H$5/2),0) -> 25.098 | G32: =IFERROR(E32*(1+$H$5/2),0) -> 31.302 | H32: =IFERROR(F32*$B$5,0) -> 12549 | I32: =IFERROR(G32*$B$5,0) -> 15651 | J32: Reception desks, shelving, built-in furniture
A33: 4 | B33: 4.2 | C33: Sanitary fittings & toilet fit-out | D33: Nr | E33: =IFERROR('Rates Reference Table'!F30*$E$5,0) -> 16.92 | F33: =IFERROR(E33*(1-$H$5/2),0) -> 15.0588 | G33: =IFERROR(E33*(1+$H$5/2),0) -> 18.7812 | H33: =IFERROR(F33*$B$5,0) -> 7529.4 | I33: =IFERROR(G33*$B$5,0) -> 9390.6 | J33: WC packs; uplift for accessible/changing facilities
A34: 4 | B34: 4.3 | C34: Kitchen / break-out area | D34: Item | E34: =IFERROR('Rates Reference Table'!F31*$E$5,0) -> 14.1 | F34: =IFERROR(E34*(1-$H$5/2),0) -> 12.549 | G34: =IFERROR(E34*(1+$H$5/2),0) -> 15.651 | H34: =IFERROR(F34*$B$5,0) -> 6274.5 | I34: =IFERROR(G34*$B$5,0) -> 7825.5 | J34: Fitted units, worktops, appliances
A35: 4 | B35: 4.4 | C35: Specialist equipment (lab/AV/med) | D35: Item | E35: =IFERROR('Rates Reference Table'!F32*$E$5,0) -> 9.4 | F35: =IFERROR(E35*(1-$H$5/2),0) -> 8.366 | G35: =IFERROR(E35*(1+$H$5/2),0) -> 10.434 | H35: =IFERROR(F35*$B$5,0) -> 4183 | I35: =IFERROR(G35*$B$5,0) -> 5217 | J35: Laboratory, medical, AV; confirm with specialist
A36: GROUP 5 — MECHANICAL & ELECTRICAL SERVICES ★ KEY ELEMENT
A37: 5 | B37: 5.1 | C37: Sanitary plumbing (1st & 2nd fix) | D37: m² | E37: =IFERROR('Rates Reference Table'!F34*$E$5,0) -> 32.9 | F37: =IFERROR(E37*(1-$H$5/2),0) -> 29.281 | G37: =IFERROR(E37*(1+$H$5/2),0) -> 36.519 | H37: =IFERROR(F37*$B$5,0) -> 14640.5 | I37: =IFERROR(G37*$B$5,0) -> 18259.5 | J37: HWS, cold water, drainage connections
A38: 5 | B38: 5.2 | C38: Heating & hot water (LTHW/heat pump) | D38: m² | E38: =IFERROR('Rates Reference Table'!F35*$E$5,0) -> 47 | F38: =IFERROR(E38*(1-$H$5/2),0) -> 41.83 | G38: =IFERROR(E38*(1+$H$5/2),0) -> 52.17 | H38: =IFERROR(F38*$B$5,0) -> 20915 | I38: =IFERROR(G38*$B$5,0) -> 26085 | J38: LTHW system or heat pump; include buffer vessel
A39: 5 | B39: 5.3 | C39: Ventilation & air handling | D39: m² | E39: =IFERROR('Rates Reference Table'!F36*$E$5,0) -> 42.3 | F39: =IFERROR(E39*(1-$H$5/2),0) -> 37.647 | G39: =IFERROR(E39*(1+$H$5/2),0) -> 46.953 | H39: =IFERROR(F39*$B$5,0) -> 18823.5 | I39: =IFERROR(G39*$B$5,0) -> 23476.5 | J39: MVHR/AHU; uplift for lab/healthcare extract (+50-100%)
A40: 5 | B40: 5.4 | C40: Air conditioning & cooling | D40: m² | E40: =IFERROR('Rates Reference Table'!F37*$E$5,0) -> 28.2 | F40: =IFERROR(E40*(1-$H$5/2),0) -> 25.098 | G40: =IFERROR(E40*(1+$H$5/2),0) -> 31.302 | H40: =IFERROR(F40*$B$5,0) -> 12549 | I40: =IFERROR(G40*$B$5,0) -> 15651 | J40: VRF/splits; omit if not in scope
A41: 5 | B41: 5.5 | C41: Gas installation | D41: Item | E41: =IFERROR('Rates Reference Table'!F38*$E$5,0) -> 9.4 | F41: =IFERROR(E41*(1-$H$5/2),0) -> 8.366 | G41: =IFERROR(E41*(1+$H$5/2),0) -> 10.434 | H41: =IFERROR(F41*$B$5,0) -> 4183 | I41: =IFERROR(G41*$B$5,0) -> 5217 | J41: Omit if all-electric; confirm with utility
A42: 5 | B42: 5.6 | C42: Sprinkler / fire suppression | D42: m² | E42: =IFERROR('Rates Reference Table'!F39*$E$5,0) -> 14.1 | F42: =IFERROR(E42*(1-$H$5/2),0) -> 12.549 | G42: =IFERROR(E42*(1+$H$5/2),0) -> 15.651 | H42: =IFERROR(F42*$B$5,0) -> 6274.5 | I42: =IFERROR(G42*$B$5,0) -> 7825.5 | J42: >18m height or insurer requirement
...

Sheet Rfb – High Spec
A1: NRM1 ESTIMATE — REFURB / FIT-OUT — HIGH SPEC / SPECIALIST
A2: Spec level: Flagship, lab, healthcare or bespoke. Heavy M&E, specialist fit-out, feature finishes. | RIBA Stage 0–1 indicative only | Base date Q2 2026
A4: Project Type: | B4: Refurb / Fit-Out | D4: Spec Level: | E4: High Spec / Specialist | G4: Region: | H4: West Midlands
A5: GIFA (m²) ▼ update: | B5: 500 | D5: BCIS Location Factor ▼: | E5: 0.94 | G5: Spread ±% ▼: | H5: 0.22
A7: Grp | B7: Sub | C7: Element / Description | D7: Unit | E7: Mid-Point £/m² | F7: Low £/m² | G7: High £/m² | H7: Total LOW (£) | I7: Total HIGH (£) | J7: Notes / Rate Driver
A8: GROUP 0 — FACILITATING WORKS
A9: 0 | B9: 0.1 | C9: Toxic/hazardous material removal | D9: Item | E9: =IFERROR('Rates Reference Table'!G6*$E$5,0) -> 37.6 | F9: =IFERROR(E9*(1-$H$5/2),0) -> 33.464 | G9: =IFERROR(E9*(1+$H$5/2),0) -> 41.736 | H9: =IFERROR(F9*$B$5,0) -> 16732 | I9: =IFERROR(G9*$B$5,0) -> 20868 | J9: Asbestos; increase if confirmed present (refurb/demo only)
A10: 0 | B10: 0.2 | C10: Demolition & structural alterations | D10: Item | E10: =IFERROR('Rates Reference Table'!G7*$E$5,0) -> 51.7 | F10: =IFERROR(E10*(1-$H$5/2),0) -> 46.013 | G10: =IFERROR(E10*(1+$H$5/2),0) -> 57.387 | H10: =IFERROR(F10*$B$5,0) -> 23006.5 | I10: =IFERROR(G10*$B$5,0) -> 28693.5 | J10: Selective or full demolition; structural openings
A11: 0 | B11: 0.3 | C11: Contaminated land remediation | D11: Item | E11: =IFERROR('Rates Reference Table'!G8*$E$5,0) -> 18.8 | F11: =IFERROR(E11*(1-$H$5/2),0) -> 16.732 | G11: =IFERROR(E11*(1+$H$5/2),0) -> 20.868 | H11: =IFERROR(F11*$B$5,0) -> 8366 | I11: =IFERROR(G11*$B$5,0) -> 10434 | J11: Brownfield/contaminated; specialist quote needed
A12: 0 | B12: 0.4 | C12: Ground stabilisation | D12: Item | E12: =IFERROR('Rates Reference Table'!G9*$E$5,0) -> 14.1 | F12: =IFERROR(E12*(1-$H$5/2),0) -> 12.549 | G12: =IFERROR(E12*(1+$H$5/2),0) -> 15.651 | H12: =IFERROR(F12*$B$5,0) -> 6274.5 | I12: =IFERROR(G12*$B$5,0) -> 7825.5 | J12: Underpinning/piling if ground risk identified
A13: GROUP 1 — SUBSTRUCTURE
A14: 1 | B14: 1.1 | C14: Standard foundations (strip/pad) | D14: m² | E14: EXCLUDED | F14: EXCLUDED | G14: EXCLUDED | H14: 0 | I14: 0 | J14: New build only; included in Group 7 rate for extensions
A15: 1 | B15: 1.2 | C15: Specialist foundations (piled) | D15: m² | E15: EXCLUDED | F15: EXCLUDED | G15: EXCLUDED | H15: 0 | I15: 0 | J15: Poor ground conditions; trigger from GI report
A16: 1 | B16: 1.3 | C16: Lowest floor construction (slab) | D16: m² | E16: EXCLUDED | F16: EXCLUDED | G16: EXCLUDED | H16: 0 | I16: 0 | J16: Ground bearing or suspended; inc DPM and insulation
A17: 1 | B17: 1.4 | C17: Basement excavation & structure | D17: Item | E17: EXCLUDED | F17: EXCLUDED | G17: EXCLUDED | H17: 0 | I17: 0 | J17: High uncertainty; specialist estimate recommended
A18: GROUP 2 — SUPERSTRUCTURE
A19: 2 | B19: 2.1 | C19: Structural frame | D19: m² | E19: =IFERROR('Rates Reference Table'!G16*$E$5,0) -> 37.6 | F19: =IFERROR(E19*(1-$H$5/2),0) -> 33.464 | G19: =IFERROR(E19*(1+$H$5/2),0) -> 41.736 | H19: =IFERROR(F19*$B$5,0) -> 16732 | I19: =IFERROR(G19*$B$5,0) -> 20868 | J19: Steel/concrete/timber; new build or major extensions only
A20: 2 | B20: 2.2 | C20: Upper floors | D20: m² | E20: =IFERROR('Rates Reference Table'!G17*$E$5,0) -> 28.2 | F20: =IFERROR(E20*(1-$H$5/2),0) -> 25.098 | G20: =IFERROR(E20*(1+$H$5/2),0) -> 31.302 | H20: =IFERROR(F20*$B$5,0) -> 12549 | I20: =IFERROR(G20*$B$5,0) -> 15651 | J20: New build or added floors; inc topping and insulation
A21: 2 | B21: 2.3 | C21: Roof structure & covering | D21: m² | E21: =IFERROR('Rates Reference Table'!G18*$E$5,0) -> 84.6 | F21: =IFERROR(E21*(1-$H$5/2),0) -> 75.294 | G21: =IFERROR(E21*(1+$H$5/2),0) -> 93.906 | H21: =IFERROR(F21*$B$5,0) -> 37647 | I21: =IFERROR(G21*$B$5,0) -> 46953 | J21: New or replacement; inc insulation, waterproofing, rainwater
A22: 2 | B22: 2.4 | C22: Stairs & ramps | D22: Item | E22: =IFERROR('Rates Reference Table'!G19*$E$5,0) -> 23.5 | F22: =IFERROR(E22*(1-$H$5/2),0) -> 20.915 | G22: =IFERROR(E22*(1+$H$5/2),0) -> 26.085 | H22: =IFERROR(F22*$B$5,0) -> 10457.5 | I22: =IFERROR(G22*$B$5,0) -> 13042.5 | J22: RC, steel or timber; accessibility ramps
A23: 2 | B23: 2.5 | C23: External walls & facade | D23: m² | E23: =IFERROR('Rates Reference Table'!G20*$E$5,0) -> 103.4 | F23: =IFERROR(E23*(1-$H$5/2),0) -> 92.026 | G23: =IFERROR(E23*(1+$H$5/2),0) -> 114.774 | H23: =IFERROR(F23*$B$5,0) -> 46013 | I23: =IFERROR(G23*$B$5,0) -> 57387 | J23: Masonry/cladding; refurb = overcladding or repair only
A24: 2 | B24: 2.6 | C24: Windows & external doors | D24: m² | E24: =IFERROR('Rates Reference Table'!G21*$E$5,0) -> 188 | F24: =IFERROR(E24*(1-$H$5/2),0) -> 167.32 | G24: =IFERROR(E24*(1+$H$5/2),0) -> 208.68 | H24: =IFERROR(F24*$B$5,0) -> 83660 | I24: =IFERROR(G24*$B$5,0) -> 104340 | J24: uPVC (low) to aluminium curtain wall (high)
A25: 2 | B25: 2.7 | C25: Internal walls & partitions | D25: m² | E25: =IFERROR('Rates Reference Table'!G22*$E$5,0) -> 56.4 | F25: =IFERROR(E25*(1-$H$5/2),0) -> 50.196 | G25: =IFERROR(E25*(1+$H$5/2),0) -> 62.604 | H25: =IFERROR(F25*$B$5,0) -> 25098 | I25: =IFERROR(G25*$B$5,0) -> 31302 | J25: Blockwork, drywall or glazed; do not double-count Grp 3
A26: 2 | B26: 2.8 | C26: Internal doors & ironmongery | D26: Nr | E26: =IFERROR('Rates Reference Table'!G23*$E$5,0) -> 37.6 | F26: =IFERROR(E26*(1-$H$5/2),0) -> 33.464 | G26: =IFERROR(E26*(1+$H$5/2),0) -> 41.736 | H26: =IFERROR(F26*$B$5,0) -> 16732 | I26: =IFERROR(G26*$B$5,0) -> 20868 | J26: Fire-rated at upper range; standard at lower
A27: GROUP 3 — INTERNAL FINISHES ★ ALWAYS INCLUDED
A28: 3 | B28: 3.1 | C28: Wall finishes | D28: m² | E28: =IFERROR('Rates Reference Table'!G25*$E$5,0) -> 70.5 | F28: =IFERROR(E28*(1-$H$5/2),0) -> 62.745 | G28: =IFERROR(E28*(1+$H$5/2),0) -> 78.255 | H28: =IFERROR(F28*$B$5,0) -> 31372.5 | I28: =IFERROR(G28*$B$5,0) -> 39127.5 | J28: Emulsion (low) → specialist tiling/feature panelling (high)
A29: 3 | B29: 3.2 | C29: Floor finishes | D29: m² | E29: =IFERROR('Rates Reference Table'!G26*$E$5,0) -> 122.2 | F29: =IFERROR(E29*(1-$H$5/2),0) -> 108.758 | G29: =IFERROR(E29*(1+$H$5/2),0) -> 135.642 | H29: =IFERROR(F29*$B$5,0) -> 54379 | I29: =IFERROR(G29*$B$5,0) -> 67821 | J29: Vinyl/carpet (low) → stone/raised access floor (high)
A30: 3 | B30: 3.3 | C30: Ceiling finishes | D30: m² | E30: =IFERROR('Rates Reference Table'!G27*$E$5,0) -> 61.1 | F30: =IFERROR(E30*(1-$H$5/2),0) -> 54.379 | G30: =IFERROR(E30*(1+$H$5/2),0) -> 67.821 | H30: =IFERROR(F30*$B$5,0) -> 27189.5 | I30: =IFERROR(G30*$B$5,0) -> 33910.5 | J30: Emulsion (low) → bespoke acoustic ceiling system (high)
A31: GROUP 4 — FITTINGS, FURNISHINGS & EQUIPMENT
A32: 4 | B32: 4.1 | C32: General fittings & built-in joinery | D32: Item | E32: =IFERROR('Rates Reference Table'!G29*$E$5,0) -> 75.2 | F32: =IFERROR(E32*(1-$H$5/2),0) -> 66.928 | G32: =IFERROR(E32*(1+$H$5/2),0) -> 83.472 | H32: =IFERROR(F32*$B$5,0) -> 33464 | I32: =IFERROR(G32*$B$5,0) -> 41736 | J32: Reception desks, shelving, built-in furniture
A33: 4 | B33: 4.2 | C33: Sanitary fittings & toilet fit-out | D33: Nr | E33: =IFERROR('Rates Reference Table'!G30*$E$5,0) -> 32.9 | F33: =IFERROR(E33*(1-$H$5/2),0) -> 29.281 | G33: =IFERROR(E33*(1+$H$5/2),0) -> 36.519 | H33: =IFERROR(F33*$B$5,0) -> 14640.5 | I33: =IFERROR(G33*$B$5,0) -> 18259.5 | J33: WC packs; uplift for accessible/changing facilities
A34: 4 | B34: 4.3 | C34: Kitchen / break-out area | D34: Item | E34: =IFERROR('Rates Reference Table'!G31*$E$5,0) -> 32.9 | F34: =IFERROR(E34*(1-$H$5/2),0) -> 29.281 | G34: =IFERROR(E34*(1+$H$5/2),0) -> 36.519 | H34: =IFERROR(F34*$B$5,0) -> 14640.5 | I34: =IFERROR(G34*$B$5,0) -> 18259.5 | J34: Fitted units, worktops, appliances
A35: 4 | B35: 4.4 | C35: Specialist equipment (lab/AV/med) | D35: Item | E35: =IFERROR('Rates Reference Table'!G32*$E$5,0) -> 75.2 | F35: =IFERROR(E35*(1-$H$5/2),0) -> 66.928 | G35: =IFERROR(E35*(1+$H$5/2),0) -> 83.472 | H35: =IFERROR(F35*$B$5,0) -> 33464 | I35: =IFERROR(G35*$B$5,0) -> 41736 | J35: Laboratory, medical, AV; confirm with specialist
A36: GROUP 5 — MECHANICAL & ELECTRICAL SERVICES ★ KEY ELEMENT
A37: 5 | B37: 5.1 | C37: Sanitary plumbing (1st & 2nd fix) | D37: m² | E37: =IFERROR('Rates Reference Table'!G34*$E$5,0) -> 61.1 | F37: =IFERROR(E37*(1-$H$5/2),0) -> 54.379 | G37: =IFERROR(E37*(1+$H$5/2),0) -> 67.821 | H37: =IFERROR(F37*$B$5,0) -> 27189.5 | I37: =IFERROR(G37*$B$5,0) -> 33910.5 | J37: HWS, cold water, drainage connections
A38: 5 | B38: 5.2 | C38: Heating & hot water (LTHW/heat pump) | D38: m² | E38: =IFERROR('Rates Reference Table'!G35*$E$5,0) -> 84.6 | F38: =IFERROR(E38*(1-$H$5/2),0) -> 75.294 | G38: =IFERROR(E38*(1+$H$5/2),0) -> 93.906 | H38: =IFERROR(F38*$B$5,0) -> 37647 | I38: =IFERROR(G38*$B$5,0) -> 46953 | J38: LTHW system or heat pump; include buffer vessel
A39: 5 | B39: 5.3 | C39: Ventilation & air handling | D39: m² | E39: =IFERROR('Rates Reference Table'!G36*$E$5,0) -> 84.6 | F39: =IFERROR(E39*(1-$H$5/2),0) -> 75.294 | G39: =IFERROR(E39*(1+$H$5/2),0) -> 93.906 | H39: =IFERROR(F39*$B$5,0) -> 37647 | I39: =IFERROR(G39*$B$5,0) -> 46953 | J39: MVHR/AHU; uplift for lab/healthcare extract (+50-100%)
A40: 5 | B40: 5.4 | C40: Air conditioning & cooling | D40: m² | E40: =IFERROR('Rates Reference Table'!G37*$E$5,0) -> 65.8 | F40: =IFERROR(E40*(1-$H$5/2),0) -> 58.562 | G40: =IFERROR(E40*(1+$H$5/2),0) -> 73.038 | H40: =IFERROR(F40*$B$5,0) -> 29281 | I40: =IFERROR(G40*$B$5,0) -> 36519 | J40: VRF/splits; omit if not in scope
A41: 5 | B41: 5.5 | C41: Gas installation | D41: Item | E41: =IFERROR('Rates Reference Table'!G38*$E$5,0) -> 14.1 | F41: =IFERROR(E41*(1-$H$5/2),0) -> 12.549 | G41: =IFERROR(E41*(1+$H$5/2),0) -> 15.651 | H41: =IFERROR(F41*$B$5,0) -> 6274.5 | I41: =IFERROR(G41*$B$5,0) -> 7825.5 | J41: Omit if all-electric; confirm with utility
A42: 5 | B42: 5.6 | C42: Sprinkler / fire suppression | D42: m² | E42: =IFERROR('Rates Reference Table'!G39*$E$5,0) -> 28.2 | F42: =IFERROR(E42*(1-$H$5/2),0) -> 25.098 | G42: =IFERROR(E42*(1+$H$5/2),0) -> 31.302 | H42: =IFERROR(F42*$B$5,0) -> 12549 | I42: =IFERROR(G42*$B$5,0) -> 15651 | J42: >18m height or insurer requirement
...

Sheet NB – Standard
A1: NRM1 ESTIMATE — NEW BUILD — STANDARD
A2: Spec level: Standard commercial/education new build. Conventional construction, standard M&E. | RIBA Stage 0–1 indicative only | Base date Q2 2026
A4: Project Type: | B4: New Build | D4: Spec Level: | E4: Standard | G4: Region: | H4: West Midlands
A5: GIFA (m²) ▼ update: | B5: 500 | D5: BCIS Location Factor ▼: | E5: 0.94 | G5: Spread ±% ▼: | H5: 0.22
A7: Grp | B7: Sub | C7: Element / Description | D7: Unit | E7: Mid-Point £/m² | F7: Low £/m² | G7: High £/m² | H7: Total LOW (£) | I7: Total HIGH (£) | J7: Notes / Rate Driver
A8: GROUP 0 — FACILITATING WORKS
A9: 0 | B9: 0.1 | C9: Toxic/hazardous material removal | D9: Item | E9: =IFERROR('Rates Reference Table'!H6*$E$5,0) -> 9.4 | F9: =IFERROR(E9*(1-$H$5/2),0) -> 8.366 | G9: =IFERROR(E9*(1+$H$5/2),0) -> 10.434 | H9: =IFERROR(F9*$B$5,0) -> 4183 | I9: =IFERROR(G9*$B$5,0) -> 5217 | J9: Asbestos; increase if confirmed present (refurb/demo only)
A10: 0 | B10: 0.2 | C10: Demolition & structural alterations | D10: Item | E10: =IFERROR('Rates Reference Table'!H7*$E$5,0) -> 14.1 | F10: =IFERROR(E10*(1-$H$5/2),0) -> 12.549 | G10: =IFERROR(E10*(1+$H$5/2),0) -> 15.651 | H10: =IFERROR(F10*$B$5,0) -> 6274.5 | I10: =IFERROR(G10*$B$5,0) -> 7825.5 | J10: Selective or full demolition; structural openings
A11: 0 | B11: 0.3 | C11: Contaminated land remediation | D11: Item | E11: =IFERROR('Rates Reference Table'!H8*$E$5,0) -> 9.4 | F11: =IFERROR(E11*(1-$H$5/2),0) -> 8.366 | G11: =IFERROR(E11*(1+$H$5/2),0) -> 10.434 | H11: =IFERROR(F11*$B$5,0) -> 4183 | I11: =IFERROR(G11*$B$5,0) -> 5217 | J11: Brownfield/contaminated; specialist quote needed
A12: 0 | B12: 0.4 | C12: Ground stabilisation | D12: Item | E12: =IFERROR('Rates Reference Table'!H9*$E$5,0) -> 7.52 | F12: =IFERROR(E12*(1-$H$5/2),0) -> 6.6928 | G12: =IFERROR(E12*(1+$H$5/2),0) -> 8.3472 | H12: =IFERROR(F12*$B$5,0) -> 3346.4 | I12: =IFERROR(G12*$B$5,0) -> 4173.6 | J12: Underpinning/piling if ground risk identified
A13: GROUP 1 — SUBSTRUCTURE
A14: 1 | B14: 1.1 | C14: Standard foundations (strip/pad) | D14: m² | E14: =IFERROR('Rates Reference Table'!H11*$E$5,0) -> 51.7 | F14: =IFERROR(E14*(1-$H$5/2),0) -> 46.013 | G14: =IFERROR(E14*(1+$H$5/2),0) -> 57.387 | H14: =IFERROR(F14*$B$5,0) -> 23006.5 | I14: =IFERROR(G14*$B$5,0) -> 28693.5 | J14: New build only; included in Group 7 rate for extensions
A15: 1 | B15: 1.2 | C15: Specialist foundations (piled) | D15: m² | E15: =IFERROR('Rates Reference Table'!H12*$E$5,0) -> 37.6 | F15: =IFERROR(E15*(1-$H$5/2),0) -> 33.464 | G15: =IFERROR(E15*(1+$H$5/2),0) -> 41.736 | H15: =IFERROR(F15*$B$5,0) -> 16732 | I15: =IFERROR(G15*$B$5,0) -> 20868 | J15: Poor ground conditions; trigger from GI report
A16: 1 | B16: 1.3 | C16: Lowest floor construction (slab) | D16: m² | E16: =IFERROR('Rates Reference Table'!H13*$E$5,0) -> 32.9 | F16: =IFERROR(E16*(1-$H$5/2),0) -> 29.281 | G16: =IFERROR(E16*(1+$H$5/2),0) -> 36.519 | H16: =IFERROR(F16*$B$5,0) -> 14640.5 | I16: =IFERROR(G16*$B$5,0) -> 18259.5 | J16: Ground bearing or suspended; inc DPM and insulation
A17: 1 | B17: 1.4 | C17: Basement excavation & structure | D17: Item | E17: =IFERROR('Rates Reference Table'!H14*$E$5,0) -> 75.2 | F17: =IFERROR(E17*(1-$H$5/2),0) -> 66.928 | G17: =IFERROR(E17*(1+$H$5/2),0) -> 83.472 | H17: =IFERROR(F17*$B$5,0) -> 33464 | I17: =IFERROR(G17*$B$5,0) -> 41736 | J17: High uncertainty; specialist estimate recommended
A18: GROUP 2 — SUPERSTRUCTURE
A19: 2 | B19: 2.1 | C19: Structural frame | D19: m² | E19: =IFERROR('Rates Reference Table'!H16*$E$5,0) -> 141 | F19: =IFERROR(E19*(1-$H$5/2),0) -> 125.49 | G19: =IFERROR(E19*(1+$H$5/2),0) -> 156.51 | H19: =IFERROR(F19*$B$5,0) -> 62745 | I19: =IFERROR(G19*$B$5,0) -> 78255 | J19: Steel/concrete/timber; new build or major extensions only
A20: 2 | B20: 2.2 | C20: Upper floors | D20: m² | E20: =IFERROR('Rates Reference Table'!H17*$E$5,0) -> 61.1 | F20: =IFERROR(E20*(1-$H$5/2),0) -> 54.379 | G20: =IFERROR(E20*(1+$H$5/2),0) -> 67.821 | H20: =IFERROR(F20*$B$5,0) -> 27189.5 | I20: =IFERROR(G20*$B$5,0) -> 33910.5 | J20: New build or added floors; inc topping and insulation
A21: 2 | B21: 2.3 | C21: Roof structure & covering | D21: m² | E21: =IFERROR('Rates Reference Table'!H18*$E$5,0) -> 70.5 | F21: =IFERROR(E21*(1-$H$5/2),0) -> 62.745 | G21: =IFERROR(E21*(1+$H$5/2),0) -> 78.255 | H21: =IFERROR(F21*$B$5,0) -> 31372.5 | I21: =IFERROR(G21*$B$5,0) -> 39127.5 | J21: New or replacement; inc insulation, waterproofing, rainwater
A22: 2 | B22: 2.4 | C22: Stairs & ramps | D22: Item | E22: =IFERROR('Rates Reference Table'!H19*$E$5,0) -> 18.8 | F22: =IFERROR(E22*(1-$H$5/2),0) -> 16.732 | G22: =IFERROR(E22*(1+$H$5/2),0) -> 20.868 | H22: =IFERROR(F22*$B$5,0) -> 8366 | I22: =IFERROR(G22*$B$5,0) -> 10434 | J22: RC, steel or timber; accessibility ramps
A23: 2 | B23: 2.5 | C23: External walls & facade | D23: m² | E23: =IFERROR('Rates Reference Table'!H20*$E$5,0) -> 188 | F23: =IFERROR(E23*(1-$H$5/2),0) -> 167.32 | G23: =IFERROR(E23*(1+$H$5/2),0) -> 208.68 | H23: =IFERROR(F23*$B$5,0) -> 83660 | I23: =IFERROR(G23*$B$5,0) -> 104340 | J23: Masonry/cladding; refurb = overcladding or repair only
A24: 2 | B24: 2.6 | C24: Windows & external doors | D24: m² | E24: =IFERROR('Rates Reference Table'!H21*$E$5,0) -> 94 | F24: =IFERROR(E24*(1-$H$5/2),0) -> 83.66 | G24: =IFERROR(E24*(1+$H$5/2),0) -> 104.34 | H24: =IFERROR(F24*$B$5,0) -> 41830 | I24: =IFERROR(G24*$B$5,0) -> 52170 | J24: uPVC (low) to aluminium curtain wall (high)
A25: 2 | B25: 2.7 | C25: Internal walls & partitions | D25: m² | E25: =IFERROR('Rates Reference Table'!H22*$E$5,0) -> 28.2 | F25: =IFERROR(E25*(1-$H$5/2),0) -> 25.098 | G25: =IFERROR(E25*(1+$H$5/2),0) -> 31.302 | H25: =IFERROR(F25*$B$5,0) -> 12549 | I25: =IFERROR(G25*$B$5,0) -> 15651 | J25: Blockwork, drywall or glazed; do not double-count Grp 3
A26: 2 | B26: 2.8 | C26: Internal doors & ironmongery | D26: Nr | E26: =IFERROR('Rates Reference Table'!H23*$E$5,0) -> 18.8 | F26: =IFERROR(E26*(1-$H$5/2),0) -> 16.732 | G26: =IFERROR(E26*(1+$H$5/2),0) -> 20.868 | H26: =IFERROR(F26*$B$5,0) -> 8366 | I26: =IFERROR(G26*$B$5,0) -> 10434 | J26: Fire-rated at upper range; standard at lower
A27: GROUP 3 — INTERNAL FINISHES ★ ALWAYS INCLUDED
A28: 3 | B28: 3.1 | C28: Wall finishes | D28: m² | E28: =IFERROR('Rates Reference Table'!H25*$E$5,0) -> 23.5 | F28: =IFERROR(E28*(1-$H$5/2),0) -> 20.915 | G28: =IFERROR(E28*(1+$H$5/2),0) -> 26.085 | H28: =IFERROR(F28*$B$5,0) -> 10457.5 | I28: =IFERROR(G28*$B$5,0) -> 13042.5 | J28: Emulsion (low) → specialist tiling/feature panelling (high)
A29: 3 | B29: 3.2 | C29: Floor finishes | D29: m² | E29: =IFERROR('Rates Reference Table'!H26*$E$5,0) -> 28.2 | F29: =IFERROR(E29*(1-$H$5/2),0) -> 25.098 | G29: =IFERROR(E29*(1+$H$5/2),0) -> 31.302 | H29: =IFERROR(F29*$B$5,0) -> 12549 | I29: =IFERROR(G29*$B$5,0) -> 15651 | J29: Vinyl/carpet (low) → stone/raised access floor (high)
A30: 3 | B30: 3.3 | C30: Ceiling finishes | D30: m² | E30: =IFERROR('Rates Reference Table'!H27*$E$5,0) -> 14.1 | F30: =IFERROR(E30*(1-$H$5/2),0) -> 12.549 | G30: =IFERROR(E30*(1+$H$5/2),0) -> 15.651 | H30: =IFERROR(F30*$B$5,0) -> 6274.5 | I30: =IFERROR(G30*$B$5,0) -> 7825.5 | J30: Emulsion (low) → bespoke acoustic ceiling system (high)
A31: GROUP 4 — FITTINGS, FURNISHINGS & EQUIPMENT
A32: 4 | B32: 4.1 | C32: General fittings & built-in joinery | D32: Item | E32: =IFERROR('Rates Reference Table'!H29*$E$5,0) -> 14.1 | F32: =IFERROR(E32*(1-$H$5/2),0) -> 12.549 | G32: =IFERROR(E32*(1+$H$5/2),0) -> 15.651 | H32: =IFERROR(F32*$B$5,0) -> 6274.5 | I32: =IFERROR(G32*$B$5,0) -> 7825.5 | J32: Reception desks, shelving, built-in furniture
A33: 4 | B33: 4.2 | C33: Sanitary fittings & toilet fit-out | D33: Nr | E33: =IFERROR('Rates Reference Table'!H30*$E$5,0) -> 9.4 | F33: =IFERROR(E33*(1-$H$5/2),0) -> 8.366 | G33: =IFERROR(E33*(1+$H$5/2),0) -> 10.434 | H33: =IFERROR(F33*$B$5,0) -> 4183 | I33: =IFERROR(G33*$B$5,0) -> 5217 | J33: WC packs; uplift for accessible/changing facilities
A34: 4 | B34: 4.3 | C34: Kitchen / break-out area | D34: Item | E34: =IFERROR('Rates Reference Table'!H31*$E$5,0) -> 7.52 | F34: =IFERROR(E34*(1-$H$5/2),0) -> 6.6928 | G34: =IFERROR(E34*(1+$H$5/2),0) -> 8.3472 | H34: =IFERROR(F34*$B$5,0) -> 3346.4 | I34: =IFERROR(G34*$B$5,0) -> 4173.6 | J34: Fitted units, worktops, appliances
A35: 4 | B35: 4.4 | C35: Specialist equipment (lab/AV/med) | D35: Item | E35: =IFERROR('Rates Reference Table'!H32*$E$5,0) -> 4.7 | F35: =IFERROR(E35*(1-$H$5/2),0) -> 4.183 | G35: =IFERROR(E35*(1+$H$5/2),0) -> 5.217 | H35: =IFERROR(F35*$B$5,0) -> 2091.5 | I35: =IFERROR(G35*$B$5,0) -> 2608.5 | J35: Laboratory, medical, AV; confirm with specialist
A36: GROUP 5 — MECHANICAL & ELECTRICAL SERVICES ★ KEY ELEMENT
A37: 5 | B37: 5.1 | C37: Sanitary plumbing (1st & 2nd fix) | D37: m² | E37: =IFERROR('Rates Reference Table'!H34*$E$5,0) -> 23.5 | F37: =IFERROR(E37*(1-$H$5/2),0) -> 20.915 | G37: =IFERROR(E37*(1+$H$5/2),0) -> 26.085 | H37: =IFERROR(F37*$B$5,0) -> 10457.5 | I37: =IFERROR(G37*$B$5,0) -> 13042.5 | J37: HWS, cold water, drainage connections
A38: 5 | B38: 5.2 | C38: Heating & hot water (LTHW/heat pump) | D38: m² | E38: =IFERROR('Rates Reference Table'!H35*$E$5,0) -> 32.9 | F38: =IFERROR(E38*(1-$H$5/2),0) -> 29.281 | G38: =IFERROR(E38*(1+$H$5/2),0) -> 36.519 | H38: =IFERROR(F38*$B$5,0) -> 14640.5 | I38: =IFERROR(G38*$B$5,0) -> 18259.5 | J38: LTHW system or heat pump; include buffer vessel
A39: 5 | B39: 5.3 | C39: Ventilation & air handling | D39: m² | E39: =IFERROR('Rates Reference Table'!H36*$E$5,0) -> 28.2 | F39: =IFERROR(E39*(1-$H$5/2),0) -> 25.098 | G39: =IFERROR(E39*(1+$H$5/2),0) -> 31.302 | H39: =IFERROR(F39*$B$5,0) -> 12549 | I39: =IFERROR(G39*$B$5,0) -> 15651 | J39: MVHR/AHU; uplift for lab/healthcare extract (+50-100%)
A40: 5 | B40: 5.4 | C40: Air conditioning & cooling | D40: m² | E40: =IFERROR('Rates Reference Table'!H37*$E$5,0) -> 14.1 | F40: =IFERROR(E40*(1-$H$5/2),0) -> 12.549 | G40: =IFERROR(E40*(1+$H$5/2),0) -> 15.651 | H40: =IFERROR(F40*$B$5,0) -> 6274.5 | I40: =IFERROR(G40*$B$5,0) -> 7825.5 | J40: VRF/splits; omit if not in scope
A41: 5 | B41: 5.5 | C41: Gas installation | D41: Item | E41: =IFERROR('Rates Reference Table'!H38*$E$5,0) -> 7.52 | F41: =IFERROR(E41*(1-$H$5/2),0) -> 6.6928 | G41: =IFERROR(E41*(1+$H$5/2),0) -> 8.3472 | H41: =IFERROR(F41*$B$5,0) -> 3346.4 | I41: =IFERROR(G41*$B$5,0) -> 4173.6 | J41: Omit if all-electric; confirm with utility
A42: 5 | B42: 5.6 | C42: Sprinkler / fire suppression | D42: m² | E42: =IFERROR('Rates Reference Table'!H39*$E$5,0) -> 9.4 | F42: =IFERROR(E42*(1-$H$5/2),0) -> 8.366 | G42: =IFERROR(E42*(1+$H$5/2),0) -> 10.434 | H42: =IFERROR(F42*$B$5,0) -> 4183 | I42: =IFERROR(G42*$B$5,0) -> 5217 | J42: >18m height or insurer requirement
...

Sheet NB – High Spec
A1: NRM1 ESTIMATE — NEW BUILD — HIGH SPEC / SPECIALIST
A2: Spec level: High specification new build — lab, healthcare, flagship or technically complex. | RIBA Stage 0–1 indicative only | Base date Q2 2026
A4: Project Type: | B4: New Build | D4: Spec Level: | E4: High Spec / Specialist | G4: Region: | H4: West Midlands
A5: GIFA (m²) ▼ update: | B5: 500 | D5: BCIS Location Factor ▼: | E5: 0.94 | G5: Spread ±% ▼: | H5: 0.22
A7: Grp | B7: Sub | C7: Element / Description | D7: Unit | E7: Mid-Point £/m² | F7: Low £/m² | G7: High £/m² | H7: Total LOW (£) | I7: Total HIGH (£) | J7: Notes / Rate Driver
A8: GROUP 0 — FACILITATING WORKS
A9: 0 | B9: 0.1 | C9: Toxic/hazardous material removal | D9: Item | E9: =IFERROR('Rates Reference Table'!I6*$E$5,0) -> 18.8 | F9: =IFERROR(E9*(1-$H$5/2),0) -> 16.732 | G9: =IFERROR(E9*(1+$H$5/2),0) -> 20.868 | H9: =IFERROR(F9*$B$5,0) -> 8366 | I9: =IFERROR(G9*$B$5,0) -> 10434 | J9: Asbestos; increase if confirmed present (refurb/demo only)
A10: 0 | B10: 0.2 | C10: Demolition & structural alterations | D10: Item | E10: =IFERROR('Rates Reference Table'!I7*$E$5,0) -> 23.5 | F10: =IFERROR(E10*(1-$H$5/2),0) -> 20.915 | G10: =IFERROR(E10*(1+$H$5/2),0) -> 26.085 | H10: =IFERROR(F10*$B$5,0) -> 10457.5 | I10: =IFERROR(G10*$B$5,0) -> 13042.5 | J10: Selective or full demolition; structural openings
A11: 0 | B11: 0.3 | C11: Contaminated land remediation | D11: Item | E11: =IFERROR('Rates Reference Table'!I8*$E$5,0) -> 18.8 | F11: =IFERROR(E11*(1-$H$5/2),0) -> 16.732 | G11: =IFERROR(E11*(1+$H$5/2),0) -> 20.868 | H11: =IFERROR(F11*$B$5,0) -> 8366 | I11: =IFERROR(G11*$B$5,0) -> 10434 | J11: Brownfield/contaminated; specialist quote needed
A12: 0 | B12: 0.4 | C12: Ground stabilisation | D12: Item | E12: =IFERROR('Rates Reference Table'!I9*$E$5,0) -> 14.1 | F12: =IFERROR(E12*(1-$H$5/2),0) -> 12.549 | G12: =IFERROR(E12*(1+$H$5/2),0) -> 15.651 | H12: =IFERROR(F12*$B$5,0) -> 6274.5 | I12: =IFERROR(G12*$B$5,0) -> 7825.5 | J12: Underpinning/piling if ground risk identified
A13: GROUP 1 — SUBSTRUCTURE
A14: 1 | B14: 1.1 | C14: Standard foundations (strip/pad) | D14: m² | E14: =IFERROR('Rates Reference Table'!I11*$E$5,0) -> 75.2 | F14: =IFERROR(E14*(1-$H$5/2),0) -> 66.928 | G14: =IFERROR(E14*(1+$H$5/2),0) -> 83.472 | H14: =IFERROR(F14*$B$5,0) -> 33464 | I14: =IFERROR(G14*$B$5,0) -> 41736 | J14: New build only; included in Group 7 rate for extensions
A15: 1 | B15: 1.2 | C15: Specialist foundations (piled) | D15: m² | E15: =IFERROR('Rates Reference Table'!I12*$E$5,0) -> 56.4 | F15: =IFERROR(E15*(1-$H$5/2),0) -> 50.196 | G15: =IFERROR(E15*(1+$H$5/2),0) -> 62.604 | H15: =IFERROR(F15*$B$5,0) -> 25098 | I15: =IFERROR(G15*$B$5,0) -> 31302 | J15: Poor ground conditions; trigger from GI report
A16: 1 | B16: 1.3 | C16: Lowest floor construction (slab) | D16: m² | E16: =IFERROR('Rates Reference Table'!I13*$E$5,0) -> 51.7 | F16: =IFERROR(E16*(1-$H$5/2),0) -> 46.013 | G16: =IFERROR(E16*(1+$H$5/2),0) -> 57.387 | H16: =IFERROR(F16*$B$5,0) -> 23006.5 | I16: =IFERROR(G16*$B$5,0) -> 28693.5 | J16: Ground bearing or suspended; inc DPM and insulation
A17: 1 | B17: 1.4 | C17: Basement excavation & structure | D17: Item | E17: =IFERROR('Rates Reference Table'!I14*$E$5,0) -> 141 | F17: =IFERROR(E17*(1-$H$5/2),0) -> 125.49 | G17: =IFERROR(E17*(1+$H$5/2),0) -> 156.51 | H17: =IFERROR(F17*$B$5,0) -> 62745 | I17: =IFERROR(G17*$B$5,0) -> 78255 | J17: High uncertainty; specialist estimate recommended
A18: GROUP 2 — SUPERSTRUCTURE
A19: 2 | B19: 2.1 | C19: Structural frame | D19: m² | E19: =IFERROR('Rates Reference Table'!I16*$E$5,0) -> 206.8 | F19: =IFERROR(E19*(1-$H$5/2),0) -> 184.052 | G19: =IFERROR(E19*(1+$H$5/2),0) -> 229.548 | H19: =IFERROR(F19*$B$5,0) -> 92026 | I19: =IFERROR(G19*$B$5,0) -> 114774 | J19: Steel/concrete/timber; new build or major extensions only
A20: 2 | B20: 2.2 | C20: Upper floors | D20: m² | E20: =IFERROR('Rates Reference Table'!I17*$E$5,0) -> 89.3 | F20: =IFERROR(E20*(1-$H$5/2),0) -> 79.477 | G20: =IFERROR(E20*(1+$H$5/2),0) -> 99.123 | H20: =IFERROR(F20*$B$5,0) -> 39738.5 | I20: =IFERROR(G20*$B$5,0) -> 49561.5 | J20: New build or added floors; inc topping and insulation
A21: 2 | B21: 2.3 | C21: Roof structure & covering | D21: m² | E21: =IFERROR('Rates Reference Table'!I18*$E$5,0) -> 112.8 | F21: =IFERROR(E21*(1-$H$5/2),0) -> 100.392 | G21: =IFERROR(E21*(1+$H$5/2),0) -> 125.208 | H21: =IFERROR(F21*$B$5,0) -> 50196 | I21: =IFERROR(G21*$B$5,0) -> 62604 | J21: New or replacement; inc insulation, waterproofing, rainwater
A22: 2 | B22: 2.4 | C22: Stairs & ramps | D22: Item | E22: =IFERROR('Rates Reference Table'!I19*$E$5,0) -> 32.9 | F22: =IFERROR(E22*(1-$H$5/2),0) -> 29.281 | G22: =IFERROR(E22*(1+$H$5/2),0) -> 36.519 | H22: =IFERROR(F22*$B$5,0) -> 14640.5 | I22: =IFERROR(G22*$B$5,0) -> 18259.5 | J22: RC, steel or timber; accessibility ramps
A23: 2 | B23: 2.5 | C23: External walls & facade | D23: m² | E23: =IFERROR('Rates Reference Table'!I20*$E$5,0) -> 300.8 | F23: =IFERROR(E23*(1-$H$5/2),0) -> 267.712 | G23: =IFERROR(E23*(1+$H$5/2),0) -> 333.888 | H23: =IFERROR(F23*$B$5,0) -> 133856 | I23: =IFERROR(G23*$B$5,0) -> 166944 | J23: Masonry/cladding; refurb = overcladding or repair only
A24: 2 | B24: 2.6 | C24: Windows & external doors | D24: m² | E24: =IFERROR('Rates Reference Table'!I21*$E$5,0) -> 150.4 | F24: =IFERROR(E24*(1-$H$5/2),0) -> 133.856 | G24: =IFERROR(E24*(1+$H$5/2),0) -> 166.944 | H24: =IFERROR(F24*$B$5,0) -> 66928 | I24: =IFERROR(G24*$B$5,0) -> 83472 | J24: uPVC (low) to aluminium curtain wall (high)
A25: 2 | B25: 2.7 | C25: Internal walls & partitions | D25: m² | E25: =IFERROR('Rates Reference Table'!I22*$E$5,0) -> 47 | F25: =IFERROR(E25*(1-$H$5/2),0) -> 41.83 | G25: =IFERROR(E25*(1+$H$5/2),0) -> 52.17 | H25: =IFERROR(F25*$B$5,0) -> 20915 | I25: =IFERROR(G25*$B$5,0) -> 26085 | J25: Blockwork, drywall or glazed; do not double-count Grp 3
A26: 2 | B26: 2.8 | C26: Internal doors & ironmongery | D26: Nr | E26: =IFERROR('Rates Reference Table'!I23*$E$5,0) -> 32.9 | F26: =IFERROR(E26*(1-$H$5/2),0) -> 29.281 | G26: =IFERROR(E26*(1+$H$5/2),0) -> 36.519 | H26: =IFERROR(F26*$B$5,0) -> 14640.5 | I26: =IFERROR(G26*$B$5,0) -> 18259.5 | J26: Fire-rated at upper range; standard at lower
A27: GROUP 3 — INTERNAL FINISHES ★ ALWAYS INCLUDED
A28: 3 | B28: 3.1 | C28: Wall finishes | D28: m² | E28: =IFERROR('Rates Reference Table'!I25*$E$5,0) -> 51.7 | F28: =IFERROR(E28*(1-$H$5/2),0) -> 46.013 | G28: =IFERROR(E28*(1+$H$5/2),0) -> 57.387 | H28: =IFERROR(F28*$B$5,0) -> 23006.5 | I28: =IFERROR(G28*$B$5,0) -> 28693.5 | J28: Emulsion (low) → specialist tiling/feature panelling (high)
A29: 3 | B29: 3.2 | C29: Floor finishes | D29: m² | E29: =IFERROR('Rates Reference Table'!I26*$E$5,0) -> 75.2 | F29: =IFERROR(E29*(1-$H$5/2),0) -> 66.928 | G29: =IFERROR(E29*(1+$H$5/2),0) -> 83.472 | H29: =IFERROR(F29*$B$5,0) -> 33464 | I29: =IFERROR(G29*$B$5,0) -> 41736 | J29: Vinyl/carpet (low) → stone/raised access floor (high)
A30: 3 | B30: 3.3 | C30: Ceiling finishes | D30: m² | E30: =IFERROR('Rates Reference Table'!I27*$E$5,0) -> 42.3 | F30: =IFERROR(E30*(1-$H$5/2),0) -> 37.647 | G30: =IFERROR(E30*(1+$H$5/2),0) -> 46.953 | H30: =IFERROR(F30*$B$5,0) -> 18823.5 | I30: =IFERROR(G30*$B$5,0) -> 23476.5 | J30: Emulsion (low) → bespoke acoustic ceiling system (high)
A31: GROUP 4 — FITTINGS, FURNISHINGS & EQUIPMENT
A32: 4 | B32: 4.1 | C32: General fittings & built-in joinery | D32: Item | E32: =IFERROR('Rates Reference Table'!I29*$E$5,0) -> 47 | F32: =IFERROR(E32*(1-$H$5/2),0) -> 41.83 | G32: =IFERROR(E32*(1+$H$5/2),0) -> 52.17 | H32: =IFERROR(F32*$B$5,0) -> 20915 | I32: =IFERROR(G32*$B$5,0) -> 26085 | J32: Reception desks, shelving, built-in furniture
A33: 4 | B33: 4.2 | C33: Sanitary fittings & toilet fit-out | D33: Nr | E33: =IFERROR('Rates Reference Table'!I30*$E$5,0) -> 20.68 | F33: =IFERROR(E33*(1-$H$5/2),0) -> 18.4052 | G33: =IFERROR(E33*(1+$H$5/2),0) -> 22.9548 | H33: =IFERROR(F33*$B$5,0) -> 9202.6 | I33: =IFERROR(G33*$B$5,0) -> 11477.4 | J33: WC packs; uplift for accessible/changing facilities
A34: 4 | B34: 4.3 | C34: Kitchen / break-out area | D34: Item | E34: =IFERROR('Rates Reference Table'!I31*$E$5,0) -> 18.8 | F34: =IFERROR(E34*(1-$H$5/2),0) -> 16.732 | G34: =IFERROR(E34*(1+$H$5/2),0) -> 20.868 | H34: =IFERROR(F34*$B$5,0) -> 8366 | I34: =IFERROR(G34*$B$5,0) -> 10434 | J34: Fitted units, worktops, appliances
A35: 4 | B35: 4.4 | C35: Specialist equipment (lab/AV/med) | D35: Item | E35: =IFERROR('Rates Reference Table'!I32*$E$5,0) -> 56.4 | F35: =IFERROR(E35*(1-$H$5/2),0) -> 50.196 | G35: =IFERROR(E35*(1+$H$5/2),0) -> 62.604 | H35: =IFERROR(F35*$B$5,0) -> 25098 | I35: =IFERROR(G35*$B$5,0) -> 31302 | J35: Laboratory, medical, AV; confirm with specialist
A36: GROUP 5 — MECHANICAL & ELECTRICAL SERVICES ★ KEY ELEMENT
A37: 5 | B37: 5.1 | C37: Sanitary plumbing (1st & 2nd fix) | D37: m² | E37: =IFERROR('Rates Reference Table'!I34*$E$5,0) -> 47 | F37: =IFERROR(E37*(1-$H$5/2),0) -> 41.83 | G37: =IFERROR(E37*(1+$H$5/2),0) -> 52.17 | H37: =IFERROR(F37*$B$5,0) -> 20915 | I37: =IFERROR(G37*$B$5,0) -> 26085 | J37: HWS, cold water, drainage connections
A38: 5 | B38: 5.2 | C38: Heating & hot water (LTHW/heat pump) | D38: m² | E38: =IFERROR('Rates Reference Table'!I35*$E$5,0) -> 65.8 | F38: =IFERROR(E38*(1-$H$5/2),0) -> 58.562 | G38: =IFERROR(E38*(1+$H$5/2),0) -> 73.038 | H38: =IFERROR(F38*$B$5,0) -> 29281 | I38: =IFERROR(G38*$B$5,0) -> 36519 | J38: LTHW system or heat pump; include buffer vessel
A39: 5 | B39: 5.3 | C39: Ventilation & air handling | D39: m² | E39: =IFERROR('Rates Reference Table'!I36*$E$5,0) -> 65.8 | F39: =IFERROR(E39*(1-$H$5/2),0) -> 58.562 | G39: =IFERROR(E39*(1+$H$5/2),0) -> 73.038 | H39: =IFERROR(F39*$B$5,0) -> 29281 | I39: =IFERROR(G39*$B$5,0) -> 36519 | J39: MVHR/AHU; uplift for lab/healthcare extract (+50-100%)
