Workbook

Sheet 1. Instructions
A1: NRM1 COST ESTIMATE TOOL — v5.4 (September 2026)
B2: Single source of truth for the scope of works and its prices, in three sheets. Prepared by Projento.
A4: THE THREE SHEETS
A5: 2. Scope and Rates | B5: Every scope item, its options and prices, where each price came from, and when the item shows and is ticked. The only place rates live.
A6: 3. Settings | B6: Everything else the app reads: workbook version, building uses, project types (with their rate columns), spec levels, intervention levels, location factors, benchmarks, inputs, quantity ratios, factors, percentage rules, retired codes.
A7: 1. Instructions | B7: This guide, the price-source key, the self-checks and the update log.
A9: HOW THE APP USES THIS WORKBOOK — it is the app's brain
A10: Runtime source | B10: The app loads this file at runtime (from GitHub, cached about 10 minutes, as with v4.5). Every item, option, rule, list, rate and percentage comes from here; the code holds none.
A11: To change a number | B11: Edit it here in Excel, save (Excel recalculates the formula cells), check the self-checks below read 0, bump the version on '3. Settings', and push to GitHub. New estimates use it within about 10 minutes.
A12: Live, no code change | B12: Rates and factors; price sources; new options and building-use rates; new items; quantity rules and ratios; Shown on / Pre-ticked on lists; conditions using the existing names; BCIS mapping; percentages, location factors, benchmarks; new project types or building uses added to their tables on '3. Settings'.
A13: Needs a code change | B13: A new column; a new pricing type; a new input name or function in quantity rules; a new kind of 'When selected' effect; renamed ▶ markers or column headers.
A14: Safety net | B14: If the file won't load, a header is missing or a self-check isn't 0, the app keeps the last good version and warns the admin. Every report records the workbook version it was priced with.
A15: Save with Excel | B15: Save from Excel or LibreOffice. Tools that don't recalculate (e.g. scripts) can leave formula cells empty, and the app will then reject the file.
A17: CODES USED ON '2. SCOPE AND RATES'
A18: Project types | B18: NB New Build · EX Extension · RF Refurbishment · FO Fit-out · EW External works only · DM Demolition only · OM Other or mixed. Several codes are separated by spaces, e.g. 'NB EX RF'. '—' means none.
A19: Building uses | B19: RES Residential · STU Student · OFF Commercial offices · EDU Education · HEA Healthcare · RET Retail · IND Industrial / warehouse · HOS Hospitality / leisure · MIX Mixed use · OTH Other · ALL any building use.
A20: Other conditions | B20: Tests joined by '&' (and), then '→ tick' or '→ untick'. Each test is a name from the inputs table, an operator (= <> < > <= >=) and a value; '=' followed by several codes means any of them. E.g. 'PT=NB & USE=RES STU & STOREYS>=4 → tick'. 'AUTO' = added by the app, never shown.
A21: Options: pick | B21: On Item rows. One = the user picks one option (drop-down). Several = the user can tick more than one option, each with its own quantity (e.g. standard + accessible toilets; passenger + goods lifts).
A22: When selected | B22: RISK: adds a risk · ASSUME: adds an assumption · RATE: changes another item's rate · SUGGEST: ticks another item (by Scope ID). Separate several with ' · '.
A23: Rate key vs Scope ID | B23: Scope ID (S-0039) = the item, e.g. Heating and hot water. Rate key (S-0039-02) = one priced line of that item, e.g. heat pump, full system. Saved projects store the rate key.
A24: Factor (× base row) | B24: Filled only on rows priced as a multiple of another row: rate = base row's rate × factor. Blank = the rate is typed in.
A26: QUANTITY RULES (column 'Quantity rule')
A27: What it is | B27: How the app estimates the quantity when the user hasn't entered one. The user's own quantity always replaces it. On Option rows, blank = same rule as the Item row.
A28: Names | B28: GIFA · STOREYS · FOOTPRINT · UPPER · EXT_AREA · DEMOLISHED · PT · USE · AGE · LEVEL — defined, with defaults, in the inputs table on '3. Settings'.
A29: Ratios | B29: r.name reads the quantity_ratios table on '3. Settings': the row for the project's building use, else the ALL row. E.g. r.m2_per_bed is 25 for student, 70 for healthcare.
A30: Functions | B30: IF(test, then, else) · ROUND(x, 0) · MAX(a, b) · SQRT(x) · Q(S-0000) = the quantity of another item · + − * / and = <> < > <= >=.
A31: Keywords | B31: ENTER = no reliable estimate; the item isn't priced until the user enters a quantity. 1 = one item or one size band.
A32: Examples | B32: Toilets: ROUND(GIFA / r.m2_per_person / r.persons_per_wc, 0). Solar PV: FOOTPRINT * r.kwp_per_m2_roof. Lifts: IF(STOREYS>=2, 1, 0).
A34: HOW TO CHANGE THINGS
A35: Change a rate | B35: Edit the rate cell on its row. Change 'Price source' to say where the new figure came from (e.g. Verified – BCIS) and add the reference in 'Source detail'. Rows with a Factor update themselves when their base row changes.
A36: Add an option | B36: Insert a row under the item. Row type = Option, same Scope ID, next Rate key (e.g. S-0039-16). Fill Option, Unit, Pricing type, rates and Price source. Leave the Item columns blank; they inherit from the Item row.
A37: Add a building-use rate | B37: Same as an option, with 'Rate building use' set to the use's code (e.g. HEA). The app uses the row matching the building use, else the ALL row.
A38: Add a scope item | B38: Insert an Item row in its group with the next unused Scope ID (never reuse one) and Rate key ending -01. Fill every Item column, the rules columns, BCIS element and a price.
A39: Add a project type or building use | B39: Give it a new code in the project_types or building_uses table on '3. Settings', then add the code to 'Shown on' / 'Pre-ticked on' / 'Relevant building uses' where it applies. Also add the code to the matching 'Unknown … codes' check below. No new columns needed.
A40: Retire an item | B40: Don't delete it. Change its rules so it isn't shown, and list its codes against the replacement item ('Replaces old codes') or on the retired_codes table.
A41: Change an estimate | B41: To change a ratio, edit its value on quantity_ratios; to change it for one building use only, add a row with that use's code. To change how an item is estimated, edit its 'Quantity rule'.
A42: Change a BCIS mapping | B42: Edit 'BCIS element' and 'Share' on the Item row. Shares must add up to 100%.
A43: Change a percentage or factor | B43: Edit the value in its table on '3. Settings'.
A44: After any change | B44: Check the self-checks below all show 0, then add a line to the update log.
A46: COLUMNS THE APP READS
...

Sheet 2. Scope and Rates
A1: SCOPE AND RATES — every scope item, its options and prices, and when it applies
A2: One row per priced line. The Item row holds the item's details and rules; Option rows below it (same Scope ID) add other options or building-use rates. Rate key and Scope ID are permanent: never change or reuse them. See '1. Instructions' for how to add or change anything.
A3: IDENTITY | D3: ITEM (on Item rows only) | I3: OPTION, QUANTITY AND PRICING | T3: RATES £ (UK mid-point, before location factor) | AB3: WHERE THE PRICE CAME FROM | AD3: WHEN IT SHOWS AND IS TICKED (Item rows; 'When selected' on any row) | AI3: BCIS AND OLD CODES (Item rows)
A4: Rate key | B4: Scope ID | C4: Row type | D4: Group | E4: Section | F4: Item | G4: What's included | H4: Options: pick | I4: Option | J4: Rate building use | K4: Default option | L4: Unit | M4: Pricing type | N4: Quantity rule | O4: Available from intervention level | P4: Pre-ticked at intervention levels | Q4: Apply band + location factor | R4: Factor (× base row) | S4: Base row (rate key) | T4: Rfb Basic | U4: Rfb Std | V4: Rfb High | W4: NB Std | X4: NB High | Y4: Ext Std | Z4: Ext High | AA4: Ext Works | AB4: Price source | AC4: Source detail | AD4: Shown on (project type codes) | AE4: Pre-ticked on (project type codes) | AF4: Relevant building uses (codes) | AG4: Other conditions | AH4: When selected (dependencies) | AI4: BCIS element 1 | AJ4: Share 1 | AK4: BCIS element 2 | AL4: Share 2 | AM4: Replaces old codes | AN4: Notes
A5: S-0001-01 | B5: S-0001 | C5: Item | D5: 0 Facilitating works | E5: — | F5: Asbestos removal | G5: Removal of asbestos and other hazardous materials in the building | H5: One | I5: Standard | J5: ALL | K5: Yes | L5: m² | M5: gifa_rate | N5: IF(PT=NB, DEMOLISHED, GIFA) | O5: 1 | Q5: Yes | T5: 25 | U5: 40 | V5: 90 | W5: 40 | X5: 90 | Y5: 10 | Z5: 20 | AA5: 40 | AB5: Derived from v4.5 | AC5: v4.5 0.1 for Refurbishment and Extension. New Build and External works columns were 0 in v4.5; set to the Refurbishment Std/High values (AI adjustment) so asbestos in a building being demolished is priced | AD5: NB EX RF FO EW DM OM | AE5: — | AF5: ALL | AG5: AGE<2000 & PT=RF FO DM → tick | AI5: 0.1 | AJ5: 1 | AM5: 0.1
A6: S-0002-01 | B6: S-0002 | C6: Item | D6: 0 Facilitating works | E6: — | F6: Demolition of existing building | G6: Whole-building demolition, soft strip and service disconnections | H6: One | I6: Standard | J6: ALL | K6: Yes | L6: m² demolished | M6: gifa_rate | N6: DEMOLISHED | O6: 4 | Q6: Yes | T6: 35 | U6: 60 | V6: 120 | W6: 60 | X6: 120 | Y6: 60 | Z6: 120 | AA6: 60 | AB6: Derived from v4.5 | AC6: v4.5 0.2 Refurbishment rates applied to every column: demolition cost doesn't depend on what replaces the building. v4.5 0.2 also covered structural alterations, now in Alterations | AD6: NB EX EW DM OM | AE6: DM | AF6: ALL | AH6: SUGGEST: S-0001 Asbestos removal · ASSUME (NB): demolished area = new GIFA unless entered | AI6: 0.2 | AJ6: 1 | AM6: 0.2
A7: S-0003-01 | B7: S-0003 | C7: Item | D7: 0 Facilitating works | E7: — | F7: Strip-out | G7: Removal of existing finishes, fittings and redundant services | H7: One | I7: Standard | J7: ALL | K7: Yes | L7: m² | M7: gifa_rate | N7: GIFA | O7: 1 | P7: 1, 2, 3, 4 | Q7: Yes | T7: 15 | U7: 25 | V7: 35 | W7: 0 | X7: 0 | Y7: 0 | Z7: 0 | AA7: 0 | AB7: v4.5 – no source recorded | AC7: v4.5 0.5. No source recorded in v4.5 | AD7: RF FO OM | AE7: — | AF7: ALL | AI7: 0.2 | AJ7: 1 | AM7: 0.5
A8: S-0004-01 | B8: S-0004 | C8: Item | D8: 0 Facilitating works | E8: — | F8: Contaminated land | G8: Remediation of contaminated ground | H8: One | I8: Standard | J8: ALL | K8: Yes | L8: m² | M8: gifa_rate | N8: IF(PT=EW, EXT_AREA, GIFA) | O8: 4 | Q8: Yes | T8: 15 | U8: 35 | V8: 60 | W8: 35 | X8: 60 | Y8: 35 | Z8: 60 | AA8: 30 | AB8: v4.5 – no source recorded | AC8: v4.5 0.3. No source recorded in v4.5 | AD8: NB EX EW DM OM | AE8: — | AF8: ALL | AI8: 0.1 | AJ8: 1 | AM8: 0.3
A9: S-0005-01 | B9: S-0005 | C9: Item | D9: 0 Facilitating works | E9: — | F9: Ground improvement | G9: Ground stabilisation and mine-working treatment (not piling) | H9: One | I9: Standard | J9: ALL | K9: Yes | L9: m² | M9: gifa_rate | N9: FOOTPRINT | O9: 4 | Q9: Yes | T9: 0 | U9: 0 | V9: 0 | W9: 20 | X9: 35 | Y9: 20 | Z9: 35 | AA9: 20 | AB9: v4.5 – no source recorded | AC9: v4.5 0.4. No source recorded in v4.5 | AD9: NB EX EW OM | AE9: — | AF9: ALL | AI9: 0.4 | AJ9: 1 | AM9: 0.4 | AN9: Piling is in Foundations
A10: S-0006-01 | B10: S-0006 | C10: Item | D10: 0 Facilitating works | E10: — | F10: Tree removal | G10: Felling and arboricultural works | H10: One | I10: Standard | J10: ALL | K10: Yes | L10: nr trees | M10: per_nr | N10: ENTER | O10: 1 | Q10: No | T10: 400 | U10: 750 | V10: 1500 | W10: 750 | X10: 1500 | Y10: 750 | Z10: 1500 | AA10: 750 | AB10: AI estimate – verify | AC10: AI estimate: felling and stump removal per tree. Spec level stands in for tree size. Not in v4.5 | AD10: NB EX EW DM OM | AE10: — | AF10: ALL | AI10: 8.1 | AJ10: 1 | AM10: 0.6
A11: S-0007-01 | B11: S-0007 | C11: Item | D11: 0 Facilitating works | E11: — | F11: Service diversions | G11: Diverting existing underground services | H11: One | I11: Size: Small | J11: ALL | L11: band | M11: per_item | N11: 1 | O11: 1 | Q11: No | T11: 15000 | U11: 15000 | V11: 15000 | W11: 15000 | X11: 15000 | Y11: 15000 | Z11: 15000 | AA11: 15000 | AB11: AI estimate – verify | AC11: AI estimate. Large = HV cable or strategic main. Not in v4.5 | AD11: NB EX EW DM OM | AE11: — | AF11: ALL | AI11: 0.5 | AJ11: 1 | AM11: 0.7
A12: S-0007-02 | B12: S-0007 | C12: Option | D12: =D11 -> 0 Facilitating works | E12: =E11 -> — | F12: =F11 -> Service diversions | I12: Size: Medium | J12: ALL | K12: Yes | L12: band | M12: per_item | O12: 1 | Q12: No | T12: 50000 | U12: 50000 | V12: 50000 | W12: 50000 | X12: 50000 | Y12: 50000 | Z12: 50000 | AA12: 50000 | AB12: AI estimate – verify | AC12: AI estimate. Large = HV cable or strategic main. Not in v4.5
A13: S-0007-03 | B13: S-0007 | C13: Option | D13: =D11 -> 0 Facilitating works | E13: =E11 -> — | F13: =F11 -> Service diversions | I13: Size: Large | J13: ALL | L13: band | M13: per_item | O13: 1 | Q13: No | T13: 150000 | U13: 150000 | V13: 150000 | W13: 150000 | X13: 150000 | Y13: 150000 | Z13: 150000 | AA13: 150000 | AB13: AI estimate – verify | AC13: AI estimate. Large = HV cable or strategic main. Not in v4.5
A14: S-0008-01 | B14: S-0008 | C14: Item | D14: 1 Substructure | E14: — | F14: Foundations | G14: Excavation and foundations | H14: One | I14: Type: Standard | J14: ALL | K14: Yes | L14: m² | M14: footprint_rate | N14: FOOTPRINT | O14: 4 | Q14: Yes | T14: 0 | U14: 0 | V14: 0 | W14: 80 | X14: 120 | Y14: 80 | Z14: 120 | AA14: 0 | AB14: v4.5 – no source recorded | AC14: v4.5 1.1. No source recorded in v4.5 | AD14: NB EX OM | AE14: NB EX | AF14: ALL | AI14: 1.1 | AJ14: 1 | AM14: 1.1, 1.2
A15: S-0008-02 | B15: S-0008 | C15: Option | D15: =D14 -> 1 Substructure | E15: =E14 -> — | F15: =F14 -> Foundations | I15: Type: Piled | J15: ALL | L15: m² | M15: footprint_rate | O15: 4 | Q15: Yes | T15: 0 | U15: 0 | V15: 0 | W15: 160 | X15: 220 | Y15: 160 | Z15: 250 | AA15: 0 | AB15: v4.5 – no source recorded | AC15: v4.5 1.2. No source recorded in v4.5
A16: S-0008-03 | B16: S-0008 | C16: Option | D16: =D14 -> 1 Substructure | E16: =E14 -> — | F16: =F14 -> Foundations | I16: Type: Not sure | J16: ALL | L16: m² | M16: footprint_rate | O16: 4 | Q16: Yes | R16: 1 | S16: S-0008-01 | T16: =T14*$R16 -> 0 | U16: =U14*$R16 -> 0 | V16: =V14*$R16 -> 0 | W16: =W14*$R16 -> 80 | X16: =X14*$R16 -> 120 | Y16: =Y14*$R16 -> 80 | Z16: =Z14*$R16 -> 120 | AA16: =AA14*$R16 -> 0 | AB16: Derived from v4.5 | AC16: Prices as Standard foundations and raises a piling risk (Dependencies) | AH16: RISK: piling may be required
A17: S-0009-01 | B17: S-0009 | C17: Item | D17: 1 Substructure | E17: — | F17: Ground floor slab | G17: Excavation, sub-base, DPM, insulation and slab | H17: One | I17: Standard | J17: ALL | K17: Yes | L17: m² | M17: footprint_rate | N17: FOOTPRINT | O17: 4 | Q17: Yes | T17: 0 | U17: 0 | V17: 0 | W17: 90 | X17: 140 | Y17: 90 | Z17: 140 | AA17: 0 | AB17: v4.5 – no source recorded | AC17: v4.5 1.3. No source recorded in v4.5 | AD17: NB EX OM | AE17: NB EX | AF17: ALL | AI17: 1.1 | AJ17: 1 | AM17: 1.3
A18: S-0010-01 | B18: S-0010 | C18: Item | D18: 1 Substructure | E18: — | F18: Basement | G18: Excavation, retaining walls and tanking | H18: One | I18: Standard | J18: ALL | K18: Yes | L18: m² basement | M18: footprint_rate | N18: FOOTPRINT | O18: 4 | Q18: Yes | T18: 0 | U18: 0 | V18: 0 | W18: 1000 | X18: 1750 | Y18: 1000 | Z18: 1750 | AA18: 0 | AB18: Derived from v4.5 | AC18: v4.5 1.4 (900 / 1,600) plus an AI allowance of £100 / £150 per m² for tanking, which moved here from retired 2.9 | AD18: NB EX OM | AE18: — | AF18: ALL | AH18: ASSUME: excavation, retaining walls and tanking included · RISK: groundwater and dewatering | AI18: 1.1 | AJ18: 1 | AM18: 1.4, 2.9, 2.10
A19: S-0011-01 | B19: S-0011 | C19: Item | D19: 2 Superstructure and envelope | E19: Structure | F19: Frame | G19: Structural frame | H19: One | I19: Standard | J19: ALL | K19: Yes | L19: m² | M19: gifa_rate | N19: GIFA | O19: 4 | Q19: Yes | T19: 0 | U19: 20 | V19: 40 | W19: 350 | X19: 550 | Y19: 130 | Z19: 200 | AA19: 0 | AB19: v4.5 – no source recorded | AC19: v4.5 2.1. No source recorded in v4.5 | AD19: NB EX OM | AE19: NB EX | AF19: ALL | AI19: 2.1 | AJ19: 1 | AM19: 2.1
A20: S-0012-01 | B20: S-0012 | C20: Item | D20: 2 Superstructure and envelope | E20: Structure | F20: Upper floors | G20: Upper floor structure, incl. balconies | H20: One | I20: Standard | J20: ALL | K20: Yes | L20: m² | M20: upperfloors_rate | N20: UPPER | O20: 4 | Q20: Yes | T20: 0 | U20: 15 | V20: 30 | W20: 78 | X20: 110 | Y20: 65 | Z20: 95 | AA20: 0 | AB20: v4.5 – no source recorded | AC20: v4.5 2.2. No source recorded in v4.5 | AD20: NB EX OM | AE20: NB EX | AF20: ALL | AG20: STOREYS<2 → untick | AI20: 2.2 | AJ20: 1 | AM20: 2.2
A21: S-0013-01 | B21: S-0013 | C21: Item | D21: 2 Superstructure and envelope | E21: Structure | F21: Stairs and ramps | G21: Stairs, ramps and balustrades | H21: One | I21: Standard | J21: ALL | K21: Yes | L21: m² | M21: gifa_rate | N21: GIFA | O21: 2 | Q21: Yes | T21: 10 | U21: 15 | V21: 25 | W21: 20 | X21: 35 | Y21: 20 | Z21: 35 | AA21: 0 | AB21: v4.5 – no source recorded | AC21: v4.5 2.4. No source recorded in v4.5 | AD21: NB EX RF OM | AE21: NB EX | AF21: ALL | AG21: STOREYS<2 → untick | AI21: 2.4 | AJ21: 1 | AM21: 2.4
A22: S-0014-01 | B22: S-0014 | C22: Item | D22: 2 Superstructure and envelope | E22: Structure | F22: Mezzanine floor | G22: Free-standing mezzanine | H22: One | I22: Standard | J22: ALL | K22: Yes | L22: m² mezzanine | M22: area_rate | N22: ENTER | O22: 4 | Q22: Yes | T22: 180 | U22: 250 | V22: 350 | W22: 250 | X22: 350 | Y22: 250 | Z22: 350 | AA22: 0 | AB22: AI estimate – verify | AC22: AI estimate per m² of mezzanine floor. v4.5 6.2 was priced per m² of whole-building GIFA, so it isn't comparable | AD22: NB EX RF FO OM | AE22: — | AF22: OFF EDU RET IND | AI22: 2.2 | AJ22: 1 | AM22: 2.12, 6.2
A23: S-0015-01 | B23: S-0015 | C23: Item | D23: 2 Superstructure and envelope | E23: Roof and walls | F23: Roof | G23: Structure, covering, insulation, drainage, access and edge protection | H23: One | I23: Standard | J23: ALL | K23: Yes | L23: m² | M23: footprint_rate | N23: FOOTPRINT | O23: 1 | Q23: Yes | T23: 35 | U23: 55 | V23: 90 | W23: 150 | X23: 250 | Y23: 75 | Z23: 120 | AA23: 0 | AB23: v4.5 – no source recorded | AC23: v4.5 2.3. No source recorded in v4.5 | AD23: NB EX RF OM | AE23: NB EX | AF23: ALL | AI23: 2.3 | AJ23: 1 | AM23: 2.3
A24: S-0016-01 | B24: S-0016 | C24: Item | D24: 2 Superstructure and envelope | E24: Roof and walls | F24: External walls | G24: Walls and facade, incl. over-cladding | H24: One | I24: Standard | J24: ALL | K24: Yes | L24: m² | M24: gifa_rate | N24: GIFA | O24: 1 | Q24: Yes | T24: 30 | U24: 60 | V24: 110 | W24: 450 | X24: 650 | Y24: 450 | Z24: 650 | AA24: 0 | AB24: v4.5 – no source recorded | AC24: v4.5 2.5. No source recorded in v4.5 | AD24: NB EX RF OM | AE24: NB EX | AF24: ALL | AI24: 2.5 | AJ24: 1 | AM24: 2.5
A25: S-0017-01 | B25: S-0017 | C25: Item | D25: 2 Superstructure and envelope | E25: Roof and walls | F25: Windows and external doors | G25: Windows, external doors and screens | H25: One | I25: Standard | J25: ALL | K25: Yes | L25: m² | M25: gifa_rate | N25: GIFA | O25: 1 | Q25: Yes | T25: 100 | U25: 150 | V25: 200 | W25: 250 | X25: 350 | Y25: 250 | Z25: 350 | AA25: 0 | AB25: v4.5 – no source recorded | AC25: v4.5 2.6. No source recorded in v4.5 | AD25: NB EX RF OM | AE25: NB EX | AF25: ALL | AI25: 2.6 | AJ25: 1 | AM25: 2.6
A26: S-0018-01 | B26: S-0018 | C26: Item | D26: 2 Superstructure and envelope | E26: Internal walls and doors | F26: Internal walls | G26: Walls and partitions | H26: One | I26: Standard | J26: ALL | K26: Yes | L26: m² | M26: gifa_rate | N26: GIFA | O26: 4 | P26: 4 | Q26: Yes | T26: 50 | U26: 80 | V26: 120 | W26: 80 | X26: 120 | Y26: 80 | Z26: 120 | AA26: 0 | AB26: v4.5 – no source recorded | AC26: v4.5 2.7. No source recorded in v4.5 | AD26: NB EX RF FO OM | AE26: NB EX | AF26: ALL | AI26: 2.7 | AJ26: 1 | AM26: 2.7
A27: S-0019-01 | B27: S-0019 | C27: Item | D27: 2 Superstructure and envelope | E27: Internal walls and doors | F27: Internal doors | G27: Doors and ironmongery, incl. fire doors | H27: One | I27: Standard | J27: ALL | K27: Yes | L27: m² | M27: gifa_rate | N27: GIFA | O27: 1 | P27: 4 | Q27: Yes | T27: 15 | U27: 35 | V27: 60 | W27: 80 | X27: 120 | Y27: 35 | Z27: 60 | AA27: 0 | AB27: v4.5 – no source recorded | AC27: v4.5 2.8. No source recorded in v4.5 | AD27: NB EX RF FO OM | AE27: NB EX | AF27: ALL | AI27: 2.8 | AJ27: 1 | AM27: 2.8
A28: S-0020-01 | B28: S-0020 | C28: Item | D28: 2 Superstructure and envelope | E28: Internal walls and doors | F28: Fire stopping | G28: Fire stopping and compartmentation upgrade | H28: One | I28: Standard | J28: ALL | K28: Yes | L28: m² | M28: gifa_rate | N28: GIFA | O28: 1 | P28: 3, 4 | Q28: Yes | T28: 15 | U28: 30 | V28: 60 | W28: 0 | X28: 0 | Y28: 15 | Z28: 30 | AA28: 0 | AB28: AI estimate – verify | AC28: AI estimate: fire stopping and compartmentation upgrade in an existing building. Not in v4.5 | AD28: EX RF FO OM | AE28: — | AF28: ALL | AI28: 2.7 | AJ28: 1 | AM28: 2.11
A29: S-0021-01 | B29: S-0021 | C29: Item | D29: 3 Internal finishes | E29: — | F29: Wall finishes | G29: Plaster, paint and tiling, incl. tanking in wet areas | H29: One | I29: Standard | J29: ALL | K29: Yes | L29: m² | M29: gifa_rate | N29: GIFA | O29: 1 | P29: 1, 2, 3, 4 | Q29: Yes | T29: 30 | U29: 55 | V29: 140 | W29: 55 | X29: 140 | Y29: 55 | Z29: 120 | AA29: 0 | AB29: v4.5 – no source recorded | AC29: v4.5 3.1. No source recorded in v4.5 | AD29: NB EX RF FO OM | AE29: NB EX | AF29: ALL | AI29: 3.1 | AJ29: 1 | AM29: 2.9, 3.1
A30: S-0022-01 | B30: S-0022 | C30: Item | D30: 3 Internal finishes | E30: — | F30: Floor finishes | G30: Screed and floor coverings, incl. tanking in wet areas | H30: One | I30: Raised access floor: No | J30: ALL | K30: Yes | L30: m² | M30: gifa_rate | N30: GIFA | O30: 1 | P30: 1, 2, 3, 4 | Q30: Yes | T30: 45 | U30: 75 | V30: 200 | W30: 75 | X30: 200 | Y30: 80 | Z30: 140 | AA30: 0 | AB30: v4.5 – no source recorded | AC30: v4.5 3.2. No source recorded in v4.5 | AD30: NB EX RF FO OM | AE30: NB EX | AF30: ALL | AI30: 3.2 | AJ30: 1 | AM30: 2.9, 3.2
A31: S-0022-02 | B31: S-0022 | C31: Option | D31: =D30 -> 3 Internal finishes | E31: =E30 -> — | F31: =F30 -> Floor finishes | I31: Raised access floor: Yes | J31: ALL | L31: m² | M31: gifa_rate | O31: 1 | Q31: Yes | T31: 90 | U31: 120 | V31: 245 | W31: 120 | X31: 245 | Y31: 125 | Z31: 185 | AA31: 0 | AB31: Derived from v4.5 | AC31: v4.5 3.2 plus an AI allowance of £45/m² for raised access floor
A32: S-0023-01 | B32: S-0023 | C32: Item | D32: 3 Internal finishes | E32: — | F32: Ceiling finishes | G32: Plasterboard or suspended ceilings | H32: One | I32: Standard | J32: ALL | K32: Yes | L32: m² | M32: gifa_rate | N32: GIFA | O32: 1 | P32: 1, 2, 3, 4 | Q32: Yes | T32: 30 | U32: 50 | V32: 140 | W32: 50 | X32: 140 | Y32: 50 | Z32: 100 | AA32: 0 | AB32: v4.5 – no source recorded | AC32: v4.5 3.3. No source recorded in v4.5 | AD32: NB EX RF FO OM | AE32: NB EX | AF32: ALL | AI32: 3.3 | AJ32: 1 | AM32: 3.3
A33: S-0024-01 | B33: S-0024 | C33: Item | D33: 4 Toilets, kitchens and fittings | E33: Toilets, bathrooms and kitchens | F33: Toilets | G33: WC pans, basins, cubicles, vanity, dryers and accessories. Pipework is in Water and drainage, tiling in Group 3 | H33: Several | I33: Standard | J33: ALL | K33: Yes | L33: nr | M33: per_nr | N33: ROUND(GIFA / r.m2_per_person / r.persons_per_wc, 0) | O33: 2 | Q33: Yes | T33: 2800 | U33: 4950 | V33: 9400 | W33: 4950 | X33: 9400 | Y33: 4950 | Z33: 9400 | AA33: 0 | AB33: Derived from v4.5 | AC33: Standard WC: v4.5 4.2-COM ware + 4.31-NR cubicle + ½ × 5.30-NR hand dryer + ¼ × 4.32-HOH vanity run (assumption: 1 dryer per 2 WCs, 1 vanity run per 4 WCs) | AD33: NB EX RF FO OM | AE33: NB EX | AF33: OFF EDU HEA RET IND HOS | AI33: 5.1 | AJ33: 0.8 | AK33: 2.7 | AL33: 0.2 | AM33: 4.2-COM, 4.2-HC, 4.2-HP, 4.31-NR, 4.32-HOH, 5.30-NR | AN33: BCIS split is an AI estimate
A34: S-0024-02 | B34: S-0024 | C34: Option | D34: =D33 -> 4 Toilets, kitchens and fittings | E34: =E33 -> Toilets, bathrooms and kitchens | F34: =F33 -> Toilets | I34: Standard | J34: HOS | L34: nr | M34: per_nr | O34: 2 | Q34: Yes | T34: 3600 | U34: 6250 | V34: 11900 | W34: 6250 | X34: 11900 | Y34: 6250 | Z34: 11900 | AA34: 0 | AB34: Derived from v4.5 | AC34: Standard WC: v4.5 4.2-HP ware + 4.31-NR cubicle + ½ × 5.30-NR hand dryer + ¼ × 4.32-HOH vanity run (assumption: 1 dryer per 2 WCs, 1 vanity run per 4 WCs)
A35: S-0024-03 | B35: S-0024 | C35: Option | D35: =D33 -> 4 Toilets, kitchens and fittings | E35: =E33 -> Toilets, bathrooms and kitchens | F35: =F33 -> Toilets | I35: Standard | J35: HEA | L35: nr | M35: per_nr | O35: 2 | Q35: Yes | T35: 4400 | U35: 7250 | V35: 12900 | W35: 7250 | X35: 12900 | Y35: 7250 | Z35: 12900 | AA35: 0 | AB35: Derived from v4.5 | AC35: Standard WC: v4.5 4.2-HC ware + 4.31-NR cubicle + ½ × 5.30-NR hand dryer + ¼ × 4.32-HOH vanity run (assumption: 1 dryer per 2 WCs, 1 vanity run per 4 WCs)
A36: S-0024-04 | B36: S-0024 | C36: Option | D36: =D33 -> 4 Toilets, kitchens and fittings | E36: =E33 -> Toilets, bathrooms and kitchens | F36: =F33 -> Toilets | I36: Accessible | J36: ALL | K36: Yes | L36: nr | M36: per_nr | N36: STOREYS * r.accessible_wc_per_floor | O36: 2 | Q36: Yes | T36: 3500 | U36: 5500 | V36: 9000 | W36: 5500 | X36: 9000 | Y36: 5500 | Z36: 9000 | AA36: 0 | AB36: AI estimate – verify | AC36: AI estimate: Doc M pack, grab rails, alarm and larger cubicle. Not in v4.5
A37: S-0024-05 | B37: S-0024 | C37: Option | D37: =D33 -> 4 Toilets, kitchens and fittings | E37: =E33 -> Toilets, bathrooms and kitchens | F37: =F33 -> Toilets | I37: Changing Places | J37: ALL | L37: nr | M37: per_nr | N37: 1 | O37: 2 | Q37: No | T37: 45000 | U37: 60000 | V37: 80000 | W37: 60000 | X37: 80000 | Y37: 60000 | Z37: 80000 | AA37: 0 | AB37: AI estimate – verify | AC37: AI estimate per Changing Places facility (hoist, adult changing bench, peninsular WC). Not in v4.5
A38: S-0025-01 | B38: S-0025 | C38: Item | D38: 4 Toilets, kitchens and fittings | E38: Toilets, bathrooms and kitchens | F38: Bathrooms and en-suites | G38: Bath or shower, WC, basin and accessories | H38: One | I38: Built in | J38: ALL | K38: Yes | L38: Nr | M38: per_nr | N38: ROUND(IF(USE=STU, GIFA / r.m2_per_bed, IF(USE=HOS, GIFA / r.m2_per_key, GIFA / r.m2_per_dwelling * r.bathrooms_per_dwelling)), 0) | O38: 2 | Q38: Yes | T38: 900 | U38: 2000 | V38: 3500 | W38: 2000 | X38: 3500 | Y38: 2000 | Z38: 3500 | AA38: 0 | AB38: v4.5 – no source recorded | AC38: v4.5 4.2-RES. No source recorded in v4.5 | AD38: NB EX RF FO OM | AE38: NB EX | AF38: RES STU HOS | AI38: 5.1 | AJ38: 1 | AM38: 4.2-HG, 4.2-RES, 6.3
A39: S-0025-02 | B39: S-0025 | C39: Option | D39: =D38 -> 4 Toilets, kitchens and fittings | E39: =E38 -> Toilets, bathrooms and kitchens | F39: =F38 -> Bathrooms and en-suites | I39: Built in | J39: HOS | L39: Nr | M39: per_nr | O39: 2 | Q39: Yes | T39: 3500 | U39: 5500 | V39: 8500 | W39: 5500 | X39: 8500 | Y39: 5500 | Z39: 8500 | AA39: 0 | AB39: v4.5 – no source recorded | AC39: v4.5 4.2-HG. No source recorded in v4.5
A40: S-0025-03 | B40: S-0025 | C40: Option | D40: =D38 -> 4 Toilets, kitchens and fittings | E40: =E38 -> Toilets, bathrooms and kitchens | F40: =F38 -> Bathrooms and en-suites | I40: Pods | J40: ALL | L40: Nr | M40: per_nr | O40: 2 | Q40: Yes | T40: 3200 | U40: 5800 | V40: 10500 | W40: 5800 | X40: 10500 | Y40: 5800 | Z40: 10500 | AA40: 0 | AB40: v4.5 – other source cited | AC40: v4.5 6.3. v4.5 cites: Offsite Solutions Q2 2026 (not verified)
...

Sheet 3. Settings
A1: SETTINGS — every other number the app reads
A2: Each table starts at its ▶ marker and ends at the first blank row. To add a row, insert it inside the table (above the blank row). Don't rename markers or headers: the app finds tables by them.
A4: ▶ workbook_info | B4: Version stamped on every report the app produces. Update on every change
A5: Field | B5: Value | C5: Notes
A6: Version | B6: 5.4 | C6: Bump on every published change (5.3, 5.4 …) and add a line to the update log
A7: Date | B7: 2026-09-24
A8: Owner | B8: Projento
A10: ▶ building_uses | B10: Q1.3 options. The Code is what '2. Scope and Rates' uses
A11: Code | B11: Building use (label on screen) | C11: Treated as residential | D11: Notes
A12: RES | B12: Residential | C12: Yes
A13: STU | B13: Student accommodation (PBSA / halls) | C13: Yes
A14: OFF | B14: Commercial offices | C14: No
A15: EDU | B15: Education | C15: No
A16: HEA | B16: Healthcare | C16: No
A17: RET | B17: Retail | C17: No
A18: IND | B18: Industrial / warehouse | C18: No
A19: HOS | B19: Hospitality / leisure | C19: No
A20: MIX | B20: Mixed use | C20: No | D20: Every item listed; nothing hidden under More items
A21: OTH | B21: Other | C21: No | D21: Every item listed; nothing hidden under More items
A22: ALL | B22: (any building use) | D22: Used on '2. Scope and Rates' only: the item or rate applies to every building use
A24: ▶ project_types | B24: Q1.2 options. The rate column read for each specification level. The Code is what '2. Scope and Rates' uses
A25: Code | B25: Project type (label on screen) | C25: Basic column | D25: Standard column | E25: High column | F25: Uses level of intervention | G25: Notes
A26: NB | B26: New Build | C26: NB Std | D26: NB Std | E26: NB High | F26: No | G26: There is no Basic new-build rate, so Basic reads NB Std
A27: EX | B27: Extension | C27: Ext Std | D27: Ext Std | E27: Ext High | F27: No | G27: New-build elements plus tie-in to the existing building
A28: RF | B28: Refurbishment | C28: Rfb Basic | D28: Rfb Std | E28: Rfb High | F28: Yes
A29: FO | B29: Fit-out | C29: Rfb Basic | D29: Rfb Std | E29: Rfb High | F29: Yes
A30: EW | B30: External works only | C30: Ext Works | D30: Ext Works | E30: Ext Works | F30: No | G30: Quantities from the external works area
A31: DM | B31: Demolition only | C31: Rfb Basic | D31: Rfb Std | E31: Rfb High | F31: No
A32: OM | B32: Other or mixed | C32: Per component | D32: Per component | E32: Per component | F32: No | G32: From v4.5: split GIFA by use/type, price each block on its own project type's columns, and sum
A34: ▶ spec_levels | B34: Q2.4 options. The level picks the Basic / Standard / High column on project_types
A35: Level | B35: Description
A36: Basic | B36: Minimum compliance; budget materials; functional finish. Student accommodation, back-of-house, warehouses.
A37: Standard | B37: Good commercial standard; durable mid-range materials. Typical offices, education, general academic space.
A38: High | B38: Flagship/premium; high-end finishes, bespoke joinery, enhanced M&E. Boardrooms, reception, executive, prestige.
A40: ▶ intervention_levels | B40: Level of intervention (Refurbishment and Fit-out only) → band multiplier and design duration (from v4.5)
A41: Level | B41: Name | C41: Band multiplier (m² rates) | D41: Description | E41: Design duration multiplier
A42: 1 | B42: Fabric and finishes only | C42: 0.8 | D42: Decoration, floor/wall finishes, ceilings, fixtures replaced in-place. No M&E work. No walls moved. Lowest cost and shortest programme. | E42: 0.5
A43: 2 | B43: Finishes with minor services | C43: 0.9 | D43: Finishes as above plus light-touch M&E: 2nd fix fixtures, replacement light fittings, sockets and switches. Existing wiring and pipework retained. No new systems. | E43: 0.7
A44: 3 | B44: Full systems replacement | C44: 1 | D44: Complete replacement of heating, plumbing and electrical systems throughout. Same layout, same positions, no structural changes. Building rewired and re-plumbed. Typical full flat or office refurbishment. | E44: 1
A45: 4 | B45: Reconfiguration or full redesign | C45: 1.15 | D45: Layout changes, walls moved or removed, or building stripped to structure and redesigned. Requires architect, structural engineer, building control, possibly planning. Highest cost and longest programme. | E45: 1.3
...
